Workbook

Sheet Dashboard
A1: EXECUTIVE DASHBOARD
A3: Project Overview
A4: Total Investment (CAPEX) | B4: =Calculations!B10 | C4: XAF
A5: Equity Required | B5: =B4*Assumptions!C125/100 | C5: XAF
A6: Senior Debt | B6: =B4*Assumptions!C128/100 | C6: XAF
A7: Mezzanine Debt | B7: =B4*Assumptions!C136/100 | C7: XAF
A8: Grant Funding | B8: =Assumptions!C142 | C8: XAF
A10: Model Start Year | B10: =Assumptions!C5
A11: Model Horizon | B11: =Assumptions!C6 | C11: years
A13: Key Returns
A14: Project IRR | B14: ='Returns Analysis'!C4 | C14: %
A15: Equity IRR | B15: ='Returns Analysis'!C5 | C15: %
A16: NPV @ 12% | B16: ='Returns Analysis'!C6 | C16: XAF
A17: Min DSCR | B17: ='Returns Analysis'!C14 | C17: x
A18: Avg EBITDA Margin | B18: ='Returns Analysis'!C10 | C18: %
A20: Development Impact (Year 10)
A21: Farmers Supported | B21: ='Development Impact'!L5 | C21: farmers
A22: Jobs Created | B22: ='Development Impact'!L17 | C22: jobs
A23: Production Volume | B23: ='Development Impact'!L24 | C23: tonnes
A24: Cumulative Tax Revenue | B24: ='Development Impact'!L34 | C24: XAF

Sheet Assumptions
A1: FINANCIAL MODEL - ASSUMPTIONS & CONTROL PANEL
A2: Instructions: ALL BLUE CELLS are inputs. Change these to update the entire model.
A4: A. PROJECT TIMELINE & PHASING
A5: Model start year | C5: 2026 | D5: INPUT
A6: Model horizon (years) | C6: 10 | D6: INPUT
A7: Construction period - Phase 1 (months) | C7: 18 | D7: INPUT
A8: Construction period - Phase 2 (months) | C8: 24 | D8: INPUT
A9: Construction period - Phase 3 (months) | C9: 36 | D9: INPUT
A11: B. PRODUCTION & CAPACITY
A12: SEED PRODUCTION
A13: G0 seed import (tonnes/year) | C13: 100 | D13: INPUT
A14: Multiplication ratio (G0→G1) | C14: 15 | D14: INPUT
A15: Seed wastage factor (%) | C15: 5 | D15: INPUT
A17: OUTGROWER NETWORK
A18: Target farmers - Year 1 | C18: 100 | D18: INPUT
A19: Target farmers - Year 2 | C19: 375 | D19: INPUT
A20: Target farmers - Year 3+ | C20: 800 | D20: INPUT
A21: Hectares per farmer | C21: 1 | D21: INPUT
A22: Yield with certified seed (tonnes/ha) | C22: 25 | D22: INPUT
A23: Yield baseline (tonnes/ha) | C23: 8 | D23: INPUT
A25: PROCESSING CAPACITY
A26: French fry line capacity (tonnes/hour) | C26: 2 | D26: INPUT
A27: Fresh-pack line capacity (tonnes/hour) | C27: 15 | D27: INPUT
A28: Operating hours per day | C28: 8 | D28: INPUT
A29: Operating days per year | C29: 300 | D29: INPUT
A30: Capacity utilization - Year 1 (%) | C30: 40 | D30: INPUT
A31: Capacity utilization - Year 2 (%) | C31: 60 | D31: INPUT
A32: Capacity utilization - Year 3+ (%) | C32: 80 | D32: INPUT
A34: C. PRICING & REVENUE
A35: SEED PRICING
A36: G1 certified seed price (XAF/kg) | C36: 800 | D36: INPUT
A37: Seed price escalation (%/year) | C37: 3 | D37: INPUT
A39: WARE POTATO PRICING
A40: Farmgate price - processing grade (XAF/kg) | C40: 200 | D40: INPUT
A41: Farmgate price - table stock (XAF/kg) | C41: 250 | D41: INPUT
A42: Fresh-pack retail price (XAF/kg) | C42: 400 | D42: INPUT
A43: Price escalation (%/year) | C43: 2 | D43: INPUT
A45: PROCESSED PRODUCTS
A46: Frozen french fries price (XAF/kg) | C46: 1200 | D46: INPUT
A47: Animal feed price (XAF/kg) | C47: 150 | D47: INPUT
...

Sheet Calculations
A1: CALCULATIONS (Auto-Calculated from Assumptions)
A3: DERIVED VALUES
A4: G1 seed output (tonnes/year) | B4: =Assumptions!C14*Assumptions!C15*(1-Assumptions!C16/100) | C4: tonnes
A5: Total Phase 1 CAPEX | B5: =(Assumptions!C84+Assumptions!C85+Assumptions!C86+Assumptions!C87)*(1+Assumptions!C88/100) | C5: XAF
A6: Total Phase 2 CAPEX | B6: =(Assumptions!C91+Assumptions!C92+Assumptions!C93+Assumptions!C94)*(1+Assumptions!C95/100) | C6: XAF
A7: Total Phase 3 CAPEX | B7: =(Assumptions!C98+Assumptions!C99+Assumptions!C100+Assumptions!C101+Assumptions!C102+Assumptions!C103)*(1+Assumptions!C104/100) | C7: XAF
A8: Total Phase 4 CAPEX | B8: =(Assumptions!C107*Assumptions!C108+Assumptions!C109*Assumptions!C110+Assumptions!C111)*(1+Assumptions!C112/100) | C8: XAF
A9: Total Phase 5 CAPEX | B9: =(Assumptions!C115+Assumptions!C116+Assumptions!C117)*(1+Assumptions!C118/100) | C9: XAF
A10: TOTAL PROJECT CAPEX | B10: =SUM(B4:B8) | C10: XAF

Sheet Revenue
A1: REVENUE PROJECTIONS
A3: Revenue Stream | B3: Year 1 | C3: Year 2 | D3: Year 3 | E3: Year 4 | F3: Year 5 | G3: Year 6 | H3: Year 7 | I3: Year 8 | J3: Year 9 | K3: Year 10
A4: SEED REVENUE
A5: G1 seed sales volume (kg) | B5: =Calculations!$B$4*1000 | C5: =Calculations!$B$4*1000 | D5: =Calculations!$B$4*1000 | E5: =Calculations!$B$4*1000 | F5: =Calculations!$B$4*1000 | G5: =Calculations!$B$4*1000 | H5: =Calculations!$B$4*1000 | I5: =Calculations!$B$4*1000 | ... K5: =Calculations!$B$4*1000
A6: G1 seed price (XAF/kg) | B6: =Assumptions!$C$43*(1+Assumptions!$C$44/100)^(COLUMN()-2) | C6: =Assumptions!$C$43*(1+Assumptions!$C$44/100)^(COLUMN()-2) | D6: =Assumptions!$C$43*(1+Assumptions!$C$44/100)^(COLUMN()-2) | E6: =Assumptions!$C$43*(1+Assumptions!$C$44/100)^(COLUMN()-2) | F6: =Assumptions!$C$43*(1+Assumptions!$C$44/100)^(COLUMN()-2) | G6: =Assumptions!$C$43*(1+Assumptions!$C$44/100)^(COLUMN()-2) | H6: =Assumptions!$C$43*(1+Assumptions!$C$44/100)^(COLUMN()-2) | I6: =Assumptions!$C$43*(1+Assumptions!$C$44/100)^(COLUMN()-2) | ... K6: =Assumptions!$C$43*(1+Assumptions!$C$44/100)^(COLUMN()-2)
A7: Seed revenue (XAF) | B7: =B5*B6 | C7: =B5*B6 | D7: =B5*B6 | E7: =B5*B6 | F7: =B5*B6 | G7: =B5*B6 | H7: =B5*B6 | I7: =B5*B6 | J7: =B5*B6 | K7: =B5*B6
A9: PROCESSED PRODUCTS REVENUE
A10: Processing volume (tonnes) | B10: =Assumptions!$C$32*Assumptions!$C$33*Assumptions!$C$34*IF(COLUMN()=2,Assumptions!$C$35,IF(COLUMN()=3,Assumptions!$C$36,Assumptions!$C$37))/100 | C10: =Assumptions!$C$32*Assumptions!$C$33*Assumptions!$C$34*IF(COLUMN()=2,Assumptions!$C$35,IF(COLUMN()=3,Assumptions!$C$36,Assumptions!$C$37))/100 | D10: =Assumptions!$C$32*Assumptions!$C$33*Assumptions!$C$34*IF(COLUMN()=2,Assumptions!$C$35,IF(COLUMN()=3,Assumptions!$C$36,Assumptions!$C$37))/100 | E10: =Assumptions!$C$32*Assumptions!$C$33*Assumptions!$C$34*IF(COLUMN()=2,Assumptions!$C$35,IF(COLUMN()=3,Assumptions!$C$36,Assumptions!$C$37))/100 | F10: =Assumptions!$C$32*Assumptions!$C$33*Assumptions!$C$34*IF(COLUMN()=2,Assumptions!$C$35,IF(COLUMN()=3,Assumptions!$C$36,Assumptions!$C$37))/100 | G10: =Assumptions!$C$32*Assumptions!$C$33*Assumptions!$C$34*IF(COLUMN()=2,Assumptions!$C$35,IF(COLUMN()=3,Assumptions!$C$36,Assumptions!$C$37))/100 | H10: =Assumptions!$C$32*Assumptions!$C$33*Assumptions!$C$34*IF(COLUMN()=2,Assumptions!$C$35,IF(COLUMN()=3,Assumptions!$C$36,Assumptions!$C$37))/100 | I10: =Assumptions!$C$32*Assumptions!$C$33*Assumptions!$C$34*IF(COLUMN()=2,Assumptions!$C$35,IF(COLUMN()=3,Assumptions!$C$36,Assumptions!$C$37))/100 | ... K10: =Assumptions!$C$32*Assumptions!$C$33*Assumptions!$C$34*IF(COLUMN()=2,Assumptions!$C$35,IF(COLUMN()=3,Assumptions!$C$36,Assumptions!$C$37))/100
A11: French fries revenue (XAF) | B11: =B11*Assumptions!$C$55/100*Assumptions!$C$51*(1+Assumptions!$C$48/100)^(COLUMN()-2)*1000 | C11: =B11*Assumptions!$C$55/100*Assumptions!$C$51*(1+Assumptions!$C$48/100)^(COLUMN()-2)*1000 | D11: =B11*Assumptions!$C$55/100*Assumptions!$C$51*(1+Assumptions!$C$48/100)^(COLUMN()-2)*1000 | E11: =B11*Assumptions!$C$55/100*Assumptions!$C$51*(1+Assumptions!$C$48/100)^(COLUMN()-2)*1000 | F11: =B11*Assumptions!$C$55/100*Assumptions!$C$51*(1+Assumptions!$C$48/100)^(COLUMN()-2)*1000 | G11: =B11*Assumptions!$C$55/100*Assumptions!$C$51*(1+Assumptions!$C$48/100)^(COLUMN()-2)*1000 | H11: =B11*Assumptions!$C$55/100*Assumptions!$C$51*(1+Assumptions!$C$48/100)^(COLUMN()-2)*1000 | I11: =B11*Assumptions!$C$55/100*Assumptions!$C$51*(1+Assumptions!$C$48/100)^(COLUMN()-2)*1000 | J11: =B11*Assumptions!$C$55/100*Assumptions!$C$51*(1+Assumptions!$C$48/100)^(COLUMN()-2)*1000 | K11: =B11*Assumptions!$C$55/100*Assumptions!$C$51*(1+Assumptions!$C$48/100)^(COLUMN()-2)*1000
A12: Fresh pack revenue (XAF) | B12: =B11*(100-Assumptions!$C$55)/100*Assumptions!$C$50*(1+Assumptions!$C$48/100)^(COLUMN()-2)*1000 | C12: =B11*(100-Assumptions!$C$55)/100*Assumptions!$C$50*(1+Assumptions!$C$48/100)^(COLUMN()-2)*1000 | D12: =B11*(100-Assumptions!$C$55)/100*Assumptions!$C$50*(1+Assumptions!$C$48/100)^(COLUMN()-2)*1000 | E12: =B11*(100-Assumptions!$C$55)/100*Assumptions!$C$50*(1+Assumptions!$C$48/100)^(COLUMN()-2)*1000 | F12: =B11*(100-Assumptions!$C$55)/100*Assumptions!$C$50*(1+Assumptions!$C$48/100)^(COLUMN()-2)*1000 | G12: =B11*(100-Assumptions!$C$55)/100*Assumptions!$C$50*(1+Assumptions!$C$48/100)^(COLUMN()-2)*1000 | H12: =B11*(100-Assumptions!$C$55)/100*Assumptions!$C$50*(1+Assumptions!$C$48/100)^(COLUMN()-2)*1000 | I12: =B11*(100-Assumptions!$C$55)/100*Assumptions!$C$50*(1+Assumptions!$C$48/100)^(COLUMN()-2)*1000 | J12: =B11*(100-Assumptions!$C$55)/100*Assumptions!$C$50*(1+Assumptions!$C$48/100)^(COLUMN()-2)*1000 | K12: =B11*(100-Assumptions!$C$55)/100*Assumptions!$C$50*(1+Assumptions!$C$48/100)^(COLUMN()-2)*1000
A14: TOTAL REVENUE (XAF) | B14: =B8+B12+B13 | C14: =B8+B12+B13 | D14: =B8+B12+B13 | E14: =B8+B12+B13 | F14: =B8+B12+B13 | G14: =B8+B12+B13 | H14: =B8+B12+B13 | I14: =B8+B12+B13 | J14: =B8+B12+B13 | K14: =B8+B12+B13

Sheet Operating Costs
A1: OPERATING COSTS
A3: Cost Category | B3: Year 1 | C3: Year 2 | D3: Year 3 | E3: Year 4 | F3: Year 5 | G3: Year 6 | H3: Year 7 | I3: Year 8 | J3: Year 9 | K3: Year 10
A4: SEED PRODUCTION COSTS
A5: G0 import cost | B5: =Assumptions!$C$68*Assumptions!$C$14*1000*(1+Assumptions!$C$119/100)^(COLUMN()-2) | C5: =Assumptions!$C$68*Assumptions!$C$14*1000*(1+Assumptions!$C$119/100)^(COLUMN()-2) | D5: =Assumptions!$C$68*Assumptions!$C$14*1000*(1+Assumptions!$C$119/100)^(COLUMN()-2) | E5: =Assumptions!$C$68*Assumptions!$C$14*1000*(1+Assumptions!$C$119/100)^(COLUMN()-2) | F5: =Assumptions!$C$68*Assumptions!$C$14*1000*(1+Assumptions!$C$119/100)^(COLUMN()-2) | G5: =Assumptions!$C$68*Assumptions!$C$14*1000*(1+Assumptions!$C$119/100)^(COLUMN()-2) | H5: =Assumptions!$C$68*Assumptions!$C$14*1000*(1+Assumptions!$C$119/100)^(COLUMN()-2) | I5: =Assumptions!$C$68*Assumptions!$C$14*1000*(1+Assumptions!$C$119/100)^(COLUMN()-2) | ... K5: =Assumptions!$C$68*Assumptions!$C$14*1000*(1+Assumptions!$C$119/100)^(COLUMN()-2)
A6: Multiplication cost | B6: =Assumptions!$C$69*Calculations!$B$4*1000*(1+Assumptions!$C$119/100)^(COLUMN()-2) | C6: =Assumptions!$C$69*Calculations!$B$4*1000*(1+Assumptions!$C$119/100)^(COLUMN()-2) | D6: =Assumptions!$C$69*Calculations!$B$4*1000*(1+Assumptions!$C$119/100)^(COLUMN()-2) | E6: =Assumptions!$C$69*Calculations!$B$4*1000*(1+Assumptions!$C$119/100)^(COLUMN()-2) | F6: =Assumptions!$C$69*Calculations!$B$4*1000*(1+Assumptions!$C$119/100)^(COLUMN()-2) | G6: =Assumptions!$C$69*Calculations!$B$4*1000*(1+Assumptions!$C$119/100)^(COLUMN()-2) | H6: =Assumptions!$C$69*Calculations!$B$4*1000*(1+Assumptions!$C$119/100)^(COLUMN()-2) | I6: =Assumptions!$C$69*Calculations!$B$4*1000*(1+Assumptions!$C$119/100)^(COLUMN()-2) | ... K6: =Assumptions!$C$69*Calculations!$B$4*1000*(1+Assumptions!$C$119/100)^(COLUMN()-2)
A7: Total seed costs | B7: =SUM(B5:B6) | C7: =SUM(B5:B6) | D7: =SUM(B5:B6) | E7: =SUM(B5:B6) | F7: =SUM(B5:B6) | G7: =SUM(B5:B6) | H7: =SUM(B5:B6) | I7: =SUM(B5:B6) | J7: =SUM(B5:B6) | K7: =SUM(B5:B6)
A9: OUTGROWER COSTS
A10: Input packages | B10: =IF(COLUMN()=2,Assumptions!$C$19,IF(COLUMN()=3,Assumptions!$C$20,Assumptions!$C$21))*Assumptions!$C$73*(1+Assumptions!$C$119/100)^(COLUMN()-2) | C10: =IF(COLUMN()=2,Assumptions!$C$19,IF(COLUMN()=3,Assumptions!$C$20,Assumptions!$C$21))*Assumptions!$C$73*(1+Assumptions!$C$119/100)^(COLUMN()-2) | D10: =IF(COLUMN()=2,Assumptions!$C$19,IF(COLUMN()=3,Assumptions!$C$20,Assumptions!$C$21))*Assumptions!$C$73*(1+Assumptions!$C$119/100)^(COLUMN()-2) | E10: =IF(COLUMN()=2,Assumptions!$C$19,IF(COLUMN()=3,Assumptions!$C$20,Assumptions!$C$21))*Assumptions!$C$73*(1+Assumptions!$C$119/100)^(COLUMN()-2) | F10: =IF(COLUMN()=2,Assumptions!$C$19,IF(COLUMN()=3,Assumptions!$C$20,Assumptions!$C$21))*Assumptions!$C$73*(1+Assumptions!$C$119/100)^(COLUMN()-2) | G10: =IF(COLUMN()=2,Assumptions!$C$19,IF(COLUMN()=3,Assumptions!$C$20,Assumptions!$C$21))*Assumptions!$C$73*(1+Assumptions!$C$119/100)^(COLUMN()-2) | H10: =IF(COLUMN()=2,Assumptions!$C$19,IF(COLUMN()=3,Assumptions!$C$20,Assumptions!$C$21))*Assumptions!$C$73*(1+Assumptions!$C$119/100)^(COLUMN()-2) | I10: =IF(COLUMN()=2,Assumptions!$C$19,IF(COLUMN()=3,Assumptions!$C$20,Assumptions!$C$21))*Assumptions!$C$73*(1+Assumptions!$C$119/100)^(COLUMN()-2) | ... K10: =IF(COLUMN()=2,Assumptions!$C$19,IF(COLUMN()=3,Assumptions!$C$20,Assumptions!$C$21))*Assumptions!$C$73*(1+Assumptions!$C$119/100)^(COLUMN()-2)
A11: Extension services | B11: =IF(COLUMN()=2,Assumptions!$C$19,IF(COLUMN()=3,Assumptions!$C$20,Assumptions!$C$21))*Assumptions!$C$74*(1+Assumptions!$C$119/100)^(COLUMN()-2) | C11: =IF(COLUMN()=2,Assumptions!$C$19,IF(COLUMN()=3,Assumptions!$C$20,Assumptions!$C$21))*Assumptions!$C$74*(1+Assumptions!$C$119/100)^(COLUMN()-2) | D11: =IF(COLUMN()=2,Assumptions!$C$19,IF(COLUMN()=3,Assumptions!$C$20,Assumptions!$C$21))*Assumptions!$C$74*(1+Assumptions!$C$119/100)^(COLUMN()-2) | E11: =IF(COLUMN()=2,Assumptions!$C$19,IF(COLUMN()=3,Assumptions!$C$20,Assumptions!$C$21))*Assumptions!$C$74*(1+Assumptions!$C$119/100)^(COLUMN()-2) | F11: =IF(COLUMN()=2,Assumptions!$C$19,IF(COLUMN()=3,Assumptions!$C$20,Assumptions!$C$21))*Assumptions!$C$74*(1+Assumptions!$C$119/100)^(COLUMN()-2) | G11: =IF(COLUMN()=2,Assumptions!$C$19,IF(COLUMN()=3,Assumptions!$C$20,Assumptions!$C$21))*Assumptions!$C$74*(1+Assumptions!$C$119/100)^(COLUMN()-2) | H11: =IF(COLUMN()=2,Assumptions!$C$19,IF(COLUMN()=3,Assumptions!$C$20,Assumptions!$C$21))*Assumptions!$C$74*(1+Assumptions!$C$119/100)^(COLUMN()-2) | I11: =IF(COLUMN()=2,Assumptions!$C$19,IF(COLUMN()=3,Assumptions!$C$20,Assumptions!$C$21))*Assumptions!$C$74*(1+Assumptions!$C$119/100)^(COLUMN()-2) | ... K11: =IF(COLUMN()=2,Assumptions!$C$19,IF(COLUMN()=3,Assumptions!$C$20,Assumptions!$C$21))*Assumptions!$C$74*(1+Assumptions!$C$119/100)^(COLUMN()-2)
A12: Total outgrower costs | B12: =SUM(B10:B11) | C12: =SUM(B10:B11) | D12: =SUM(B10:B11) | E12: =SUM(B10:B11) | F12: =SUM(B10:B11) | G12: =SUM(B10:B11) | H12: =SUM(B10:B11) | I12: =SUM(B10:B11) | J12: =SUM(B10:B11) | K12: =SUM(B10:B11)
A14: PROCESSING COSTS
A15: Direct labor | B15: =Revenue!B11*1000*(Assumptions!$C$78+Assumptions!$C$79+Assumptions!$C$80+Assumptions!$C$81+Assumptions!$C$82)*(1+Assumptions!$C$119/100)^(COLUMN()-2) | C15: =Revenue!B11*1000*(Assumptions!$C$78+Assumptions!$C$79+Assumptions!$C$80+Assumptions!$C$81+Assumptions!$C$82)*(1+Assumptions!$C$119/100)^(COLUMN()-2) | D15: =Revenue!B11*1000*(Assumptions!$C$78+Assumptions!$C$79+Assumptions!$C$80+Assumptions!$C$81+Assumptions!$C$82)*(1+Assumptions!$C$119/100)^(COLUMN()-2) | E15: =Revenue!B11*1000*(Assumptions!$C$78+Assumptions!$C$79+Assumptions!$C$80+Assumptions!$C$81+Assumptions!$C$82)*(1+Assumptions!$C$119/100)^(COLUMN()-2) | F15: =Revenue!B11*1000*(Assumptions!$C$78+Assumptions!$C$79+Assumptions!$C$80+Assumptions!$C$81+Assumptions!$C$82)*(1+Assumptions!$C$119/100)^(COLUMN()-2) | G15: =Revenue!B11*1000*(Assumptions!$C$78+Assumptions!$C$79+Assumptions!$C$80+Assumptions!$C$81+Assumptions!$C$82)*(1+Assumptions!$C$119/100)^(COLUMN()-2) | H15: =Revenue!B11*1000*(Assumptions!$C$78+Assumptions!$C$79+Assumptions!$C$80+Assumptions!$C$81+Assumptions!$C$82)*(1+Assumptions!$C$119/100)^(COLUMN()-2) | I15: =Revenue!B11*1000*(Assumptions!$C$78+Assumptions!$C$79+Assumptions!$C$80+Assumptions!$C$81+Assumptions!$C$82)*(1+Assumptions!$C$119/100)^(COLUMN()-2) | J15: =Revenue!B11*1000*(Assumptions!$C$78+Assumptions!$C$79+Assumptions!$C$80+Assumptions!$C$81+Assumptions!$C$82)*(1+Assumptions!$C$119/100)^(COLUMN()-2) | K15: =Revenue!B11*1000*(Assumptions!$C$78+Assumptions!$C$79+Assumptions!$C$80+Assumptions!$C$81+Assumptions!$C$82)*(1+Assumptions!$C$119/100)^(COLUMN()-2)
A16: Maintenance | B16: =Calculations!$B$7*Assumptions!$C$83/100*(1+Assumptions!$C$119/100)^(COLUMN()-2) | C16: =Calculations!$B$7*Assumptions!$C$83/100*(1+Assumptions!$C$119/100)^(COLUMN()-2) | D16: =Calculations!$B$7*Assumptions!$C$83/100*(1+Assumptions!$C$119/100)^(COLUMN()-2) | E16: =Calculations!$B$7*Assumptions!$C$83/100*(1+Assumptions!$C$119/100)^(COLUMN()-2) | F16: =Calculations!$B$7*Assumptions!$C$83/100*(1+Assumptions!$C$119/100)^(COLUMN()-2) | G16: =Calculations!$B$7*Assumptions!$C$83/100*(1+Assumptions!$C$119/100)^(COLUMN()-2) | H16: =Calculations!$B$7*Assumptions!$C$83/100*(1+Assumptions!$C$119/100)^(COLUMN()-2) | I16: =Calculations!$B$7*Assumptions!$C$83/100*(1+Assumptions!$C$119/100)^(COLUMN()-2) | ... K16: =Calculations!$B$7*Assumptions!$C$83/100*(1+Assumptions!$C$119/100)^(COLUMN()-2)
A17: Total processing costs | B17: =SUM(B15:B16) | C17: =SUM(B15:B16) | D17: =SUM(B15:B16) | E17: =SUM(B15:B16) | F17: =SUM(B15:B16) | G17: =SUM(B15:B16) | H17: =SUM(B15:B16) | I17: =SUM(B15:B16) | J17: =SUM(B15:B16) | K17: =SUM(B15:B16)
A19: OVERHEAD & ADMINISTRATION
A20: Salaries | B20: =(Assumptions!$C$86+Assumptions!$C$87+Assumptions!$C$88)*12*(1+Assumptions!$C$119/100)^(COLUMN()-2) | C20: =(Assumptions!$C$86+Assumptions!$C$87+Assumptions!$C$88)*12*(1+Assumptions!$C$119/100)^(COLUMN()-2) | D20: =(Assumptions!$C$86+Assumptions!$C$87+Assumptions!$C$88)*12*(1+Assumptions!$C$119/100)^(COLUMN()-2) | E20: =(Assumptions!$C$86+Assumptions!$C$87+Assumptions!$C$88)*12*(1+Assumptions!$C$119/100)^(COLUMN()-2) | F20: =(Assumptions!$C$86+Assumptions!$C$87+Assumptions!$C$88)*12*(1+Assumptions!$C$119/100)^(COLUMN()-2) | G20: =(Assumptions!$C$86+Assumptions!$C$87+Assumptions!$C$88)*12*(1+Assumptions!$C$119/100)^(COLUMN()-2) | H20: =(Assumptions!$C$86+Assumptions!$C$87+Assumptions!$C$88)*12*(1+Assumptions!$C$119/100)^(COLUMN()-2) | I20: =(Assumptions!$C$86+Assumptions!$C$87+Assumptions!$C$88)*12*(1+Assumptions!$C$119/100)^(COLUMN()-2) | ... K20: =(Assumptions!$C$86+Assumptions!$C$87+Assumptions!$C$88)*12*(1+Assumptions!$C$119/100)^(COLUMN()-2)
A21: Professional services | B21: =Assumptions!$C$90*(1+Assumptions!$C$119/100)^(COLUMN()-2) | C21: =Assumptions!$C$90*(1+Assumptions!$C$119/100)^(COLUMN()-2) | D21: =Assumptions!$C$90*(1+Assumptions!$C$119/100)^(COLUMN()-2) | E21: =Assumptions!$C$90*(1+Assumptions!$C$119/100)^(COLUMN()-2) | F21: =Assumptions!$C$90*(1+Assumptions!$C$119/100)^(COLUMN()-2) | G21: =Assumptions!$C$90*(1+Assumptions!$C$119/100)^(COLUMN()-2) | H21: =Assumptions!$C$90*(1+Assumptions!$C$119/100)^(COLUMN()-2) | I21: =Assumptions!$C$90*(1+Assumptions!$C$119/100)^(COLUMN()-2) | ... K21: =Assumptions!$C$90*(1+Assumptions!$C$119/100)^(COLUMN()-2)
A22: Total overhead | B22: =SUM(B20:B21) | C22: =SUM(B20:B21) | D22: =SUM(B20:B21) | E22: =SUM(B20:B21) | F22: =SUM(B20:B21) | G22: =SUM(B20:B21) | H22: =SUM(B20:B21) | I22: =SUM(B20:B21) | J22: =SUM(B20:B21) | K22: =SUM(B20:B21)
A24: LOGISTICS
A25: Transport | B25: =Revenue!B11*Assumptions!$C$93*Assumptions!$C$94*(1+Assumptions!$C$119/100)^(COLUMN()-2) | C25: =Revenue!B11*Assumptions!$C$93*Assumptions!$C$94*(1+Assumptions!$C$119/100)^(COLUMN()-2) | D25: =Revenue!B11*Assumptions!$C$93*Assumptions!$C$94*(1+Assumptions!$C$119/100)^(COLUMN()-2) | E25: =Revenue!B11*Assumptions!$C$93*Assumptions!$C$94*(1+Assumptions!$C$119/100)^(COLUMN()-2) | F25: =Revenue!B11*Assumptions!$C$93*Assumptions!$C$94*(1+Assumptions!$C$119/100)^(COLUMN()-2) | G25: =Revenue!B11*Assumptions!$C$93*Assumptions!$C$94*(1+Assumptions!$C$119/100)^(COLUMN()-2) | H25: =Revenue!B11*Assumptions!$C$93*Assumptions!$C$94*(1+Assumptions!$C$119/100)^(COLUMN()-2) | I25: =Revenue!B11*Assumptions!$C$93*Assumptions!$C$94*(1+Assumptions!$C$119/100)^(COLUMN()-2) | J25: =Revenue!B11*Assumptions!$C$93*Assumptions!$C$94*(1+Assumptions!$C$119/100)^(COLUMN()-2) | K25: =Revenue!B11*Assumptions!$C$93*Assumptions!$C$94*(1+Assumptions!$C$119/100)^(COLUMN()-2)
A26: Cold storage | B26: =Revenue!B11*Assumptions!$C$95*(1+Assumptions!$C$119/100)^(COLUMN()-2) | C26: =Revenue!B11*Assumptions!$C$95*(1+Assumptions!$C$119/100)^(COLUMN()-2) | D26: =Revenue!B11*Assumptions!$C$95*(1+Assumptions!$C$119/100)^(COLUMN()-2) | E26: =Revenue!B11*Assumptions!$C$95*(1+Assumptions!$C$119/100)^(COLUMN()-2) | F26: =Revenue!B11*Assumptions!$C$95*(1+Assumptions!$C$119/100)^(COLUMN()-2) | G26: =Revenue!B11*Assumptions!$C$95*(1+Assumptions!$C$119/100)^(COLUMN()-2) | H26: =Revenue!B11*Assumptions!$C$95*(1+Assumptions!$C$119/100)^(COLUMN()-2) | I26: =Revenue!B11*Assumptions!$C$95*(1+Assumptions!$C$119/100)^(COLUMN()-2) | J26: =Revenue!B11*Assumptions!$C$95*(1+Assumptions!$C$119/100)^(COLUMN()-2) | K26: =Revenue!B11*Assumptions!$C$95*(1+Assumptions!$C$119/100)^(COLUMN()-2)
A27: Total logistics | B27: =SUM(B25:B26) | C27: =SUM(B25:B26) | D27: =SUM(B25:B26) | E27: =SUM(B25:B26) | F27: =SUM(B25:B26) | G27: =SUM(B25:B26) | H27: =SUM(B25:B26) | I27: =SUM(B25:B26) | J27: =SUM(B25:B26) | K27: =SUM(B25:B26)
A29: TOTAL OPERATING COSTS | B29: =B7+B12+B17+B22+B27 | C29: =B7+B12+B17+B22+B27 | D29: =B7+B12+B17+B22+B27 | E29: =B7+B12+B17+B22+B27 | F29: =B7+B12+B17+B22+B27 | G29: =B7+B12+B17+B22+B27 | H29: =B7+B12+B17+B22+B27 | I29: =B7+B12+B17+B22+B27 | J29: =B7+B12+B17+B22+B27 | K29: =B7+B12+B17+B22+B27

Sheet CAPEX Schedule
A1: CAPITAL EXPENDITURE SCHEDULE
A3: Phase / Asset | B3: Total Budget | C3: Year 1 | D3: Year 2 | E3: Year 3 | F3: Year 4 | G3: Year 5 | H3: Year 6 | I3: Year 7 | J3: Year 8 | K3: Year 9 | L3: Year 10
A4: PHASE 1: Seed Multiplication | B4: =Calculations!$B$5 | C4: =$B4*0.6 | D4: =$B4*0.4 | E4: 0 | F4: 0 | G4: 0 | H4: 0 | I4: 0 | J4: 0 | K4: 0 | L4: 0
A5: PHASE 2: Outgrower Network | B5: =Calculations!$B$6 | C5: 0 | D5: =$B5*0.5 | E5: =$B5*0.5 | F5: 0 | G5: 0 | H5: 0 | I5: 0 | J5: 0 | K5: 0 | L5: 0
A6: PHASE 3: Processing Facility | B6: =Calculations!$B$7 | C6: 0 | D6: =$B6*0.2 | E6: =$B6*0.5 | F6: =$B6*0.3 | G6: 0 | H6: 0 | I6: 0 | J6: 0 | K6: 0 | L6: 0
A7: PHASE 4: Logistics | B7: =Calculations!$B$8 | C7: 0 | D7: 0 | E7: 0 | F7: =$B7*0.7 | G7: =$B7*0.3 | H7: 0 | I7: 0 | J7: 0 | K7: 0 | L7: 0
A8: PHASE 5: Circular Economy | B8: =Calculations!$B$9 | C8: 0 | D8: 0 | E8: 0 | F8: 0 | G8: =$B8*1.0 | H8: 0 | I8: 0 | J8: 0 | K8: 0 | L8: 0
C9: 0 | D9: 0 | E9: 0 | F9: 0 | G9: 0 | H9: 0 | I9: 0 | J9: 0 | K9: 0 | L9: 0
A10: TOTAL ANNUAL CAPEX | B10: =Calculations!$B$10
C11: 0 | D11: 0 | E11: 0 | F11: 0 | G11: 0 | H11: 0 | I11: 0 | J11: 0 | K11: 0 | L11: 0
A12: Cumulative CAPEX

Sheet Debt Schedule
A1: DEBT SCHEDULE & AMORTIZATION
A3: Item | B3: Year 1 | C3: Year 2 | D3: Year 3 | E3: Year 4 | F3: Year 5 | G3: Year 6 | H3: Year 7 | I3: Year 8 | J3: Year 9 | K3: Year 10
A4: SENIOR DEBT
A5: Opening balance | B5: =IF(COLUMN()=2,0,OFFSET($B6,0,COLUMN()-3)) | C5: =IF(COLUMN()=2,0,OFFSET($B6,0,COLUMN()-3)) | D5: =IF(COLUMN()=2,0,OFFSET($B6,0,COLUMN()-3)) | E5: =IF(COLUMN()=2,0,OFFSET($B6,0,COLUMN()-3)) | F5: =IF(COLUMN()=2,0,OFFSET($B6,0,COLUMN()-3)) | G5: =IF(COLUMN()=2,0,OFFSET($B6,0,COLUMN()-3)) | H5: =IF(COLUMN()=2,0,OFFSET($B6,0,COLUMN()-3)) | I5: =IF(COLUMN()=2,0,OFFSET($B6,0,COLUMN()-3)) | ... K5: =IF(COLUMN()=2,0,OFFSET($B6,0,COLUMN()-3))
A6: Drawdowns | B6: ='CAPEX Schedule'!C11*Assumptions!$C$128/100 | C6: ='CAPEX Schedule'!C11*Assumptions!$C$128/100 | D6: ='CAPEX Schedule'!C11*Assumptions!$C$128/100 | E6: ='CAPEX Schedule'!C11*Assumptions!$C$128/100 | F6: ='CAPEX Schedule'!C11*Assumptions!$C$128/100 | G6: ='CAPEX Schedule'!C11*Assumptions!$C$128/100 | H6: ='CAPEX Schedule'!C11*Assumptions!$C$128/100 | I6: ='CAPEX Schedule'!C11*Assumptions!$C$128/100 | J6: ='CAPEX Schedule'!C11*Assumptions!$C$128/100 | K6: ='CAPEX Schedule'!C11*Assumptions!$C$128/100
A7: Principal repayment | B7: =IF(COLUMN()-2<=Assumptions!$C$131,0,Calculations!$B$10*Assumptions!$C$128/100/(Assumptions!$C$130-Assumptions!$C$131)) | C7: =IF(COLUMN()-2<=Assumptions!$C$131,0,Calculations!$B$10*Assumptions!$C$128/100/(Assumptions!$C$130-Assumptions!$C$131)) | D7: =IF(COLUMN()-2<=Assumptions!$C$131,0,Calculations!$B$10*Assumptions!$C$128/100/(Assumptions!$C$130-Assumptions!$C$131)) | E7: =IF(COLUMN()-2<=Assumptions!$C$131,0,Calculations!$B$10*Assumptions!$C$128/100/(Assumptions!$C$130-Assumptions!$C$131)) | F7: =IF(COLUMN()-2<=Assumptions!$C$131,0,Calculations!$B$10*Assumptions!$C$128/100/(Assumptions!$C$130-Assumptions!$C$131)) | G7: =IF(COLUMN()-2<=Assumptions!$C$131,0,Calculations!$B$10*Assumptions!$C$128/100/(Assumptions!$C$130-Assumptions!$C$131)) | H7: =IF(COLUMN()-2<=Assumptions!$C$131,0,Calculations!$B$10*Assumptions!$C$128/100/(Assumptions!$C$130-Assumptions!$C$131)) | I7: =IF(COLUMN()-2<=Assumptions!$C$131,0,Calculations!$B$10*Assumptions!$C$128/100/(Assumptions!$C$130-Assumptions!$C$131)) | ... K7: =IF(COLUMN()-2<=Assumptions!$C$131,0,Calculations!$B$10*Assumptions!$C$128/100/(Assumptions!$C$130-Assumptions!$C$131))
A8: Closing balance | B8: =B5+B6-B7 | C8: =B5+B6-B7 | D8: =B5+B6-B7 | E8: =B5+B6-B7 | F8: =B5+B6-B7 | G8: =B5+B6-B7 | H8: =B5+B6-B7 | I8: =B5+B6-B7 | J8: =B5+B6-B7 | K8: =B5+B6-B7
A9: Interest expense | B9: =(B5+B8)/2*Assumptions!$C$129/100 | C9: =(B5+B8)/2*Assumptions!$C$129/100 | D9: =(B5+B8)/2*Assumptions!$C$129/100 | E9: =(B5+B8)/2*Assumptions!$C$129/100 | F9: =(B5+B8)/2*Assumptions!$C$129/100 | G9: =(B5+B8)/2*Assumptions!$C$129/100 | H9: =(B5+B8)/2*Assumptions!$C$129/100 | I9: =(B5+B8)/2*Assumptions!$C$129/100 | J9: =(B5+B8)/2*Assumptions!$C$129/100 | K9: =(B5+B8)/2*Assumptions!$C$129/100
A10: Commitment fee | B10: =(Calculations!$B$10*Assumptions!$C$128/100-B8)*Assumptions!$C$133/100 | C10: =(Calculations!$B$10*Assumptions!$C$128/100-B8)*Assumptions!$C$133/100 | D10: =(Calculations!$B$10*Assumptions!$C$128/100-B8)*Assumptions!$C$133/100 | E10: =(Calculations!$B$10*Assumptions!$C$128/100-B8)*Assumptions!$C$133/100 | F10: =(Calculations!$B$10*Assumptions!$C$128/100-B8)*Assumptions!$C$133/100 | G10: =(Calculations!$B$10*Assumptions!$C$128/100-B8)*Assumptions!$C$133/100 | H10: =(Calculations!$B$10*Assumptions!$C$128/100-B8)*Assumptions!$C$133/100 | I10: =(Calculations!$B$10*Assumptions!$C$128/100-B8)*Assumptions!$C$133/100 | J10: =(Calculations!$B$10*Assumptions!$C$128/100-B8)*Assumptions!$C$133/100 | K10: =(Calculations!$B$10*Assumptions!$C$128/100-B8)*Assumptions!$C$133/100
A11: Total debt service | B11: =B7+B9+B10 | C11: =B7+B9+B10 | D11: =B7+B9+B10 | E11: =B7+B9+B10 | F11: =B7+B9+B10 | G11: =B7+B9+B10 | H11: =B7+B9+B10 | I11: =B7+B9+B10 | J11: =B7+B9+B10 | K11: =B7+B9+B10
A13: MEZZANINE DEBT
A14: Opening balance | B14: =IF(COLUMN()=2,0,OFFSET($B14,0,COLUMN()-3)) | C14: =IF(COLUMN()=2,0,OFFSET($B14,0,COLUMN()-3)) | D14: =IF(COLUMN()=2,0,OFFSET($B14,0,COLUMN()-3)) | E14: =IF(COLUMN()=2,0,OFFSET($B14,0,COLUMN()-3)) | F14: =IF(COLUMN()=2,0,OFFSET($B14,0,COLUMN()-3)) | G14: =IF(COLUMN()=2,0,OFFSET($B14,0,COLUMN()-3)) | H14: =IF(COLUMN()=2,0,OFFSET($B14,0,COLUMN()-3)) | I14: =IF(COLUMN()=2,0,OFFSET($B14,0,COLUMN()-3)) | ... K14: =IF(COLUMN()=2,0,OFFSET($B14,0,COLUMN()-3))
A15: Drawdowns | B15: ='CAPEX Schedule'!C11*Assumptions!$C$136/100 | C15: ='CAPEX Schedule'!C11*Assumptions!$C$136/100 | D15: ='CAPEX Schedule'!C11*Assumptions!$C$136/100 | E15: ='CAPEX Schedule'!C11*Assumptions!$C$136/100 | F15: ='CAPEX Schedule'!C11*Assumptions!$C$136/100 | G15: ='CAPEX Schedule'!C11*Assumptions!$C$136/100 | H15: ='CAPEX Schedule'!C11*Assumptions!$C$136/100 | I15: ='CAPEX Schedule'!C11*Assumptions!$C$136/100 | J15: ='CAPEX Schedule'!C11*Assumptions!$C$136/100 | K15: ='CAPEX Schedule'!C11*Assumptions!$C$136/100
A16: Principal repayment | B16: =IF(COLUMN()-2<=Assumptions!$C$139,0,Calculations!$B$10*Assumptions!$C$136/100/(Assumptions!$C$138-Assumptions!$C$139)) | C16: =IF(COLUMN()-2<=Assumptions!$C$139,0,Calculations!$B$10*Assumptions!$C$136/100/(Assumptions!$C$138-Assumptions!$C$139)) | D16: =IF(COLUMN()-2<=Assumptions!$C$139,0,Calculations!$B$10*Assumptions!$C$136/100/(Assumptions!$C$138-Assumptions!$C$139)) | E16: =IF(COLUMN()-2<=Assumptions!$C$139,0,Calculations!$B$10*Assumptions!$C$136/100/(Assumptions!$C$138-Assumptions!$C$139)) | F16: =IF(COLUMN()-2<=Assumptions!$C$139,0,Calculations!$B$10*Assumptions!$C$136/100/(Assumptions!$C$138-Assumptions!$C$139)) | G16: =IF(COLUMN()-2<=Assumptions!$C$139,0,Calculations!$B$10*Assumptions!$C$136/100/(Assumptions!$C$138-Assumptions!$C$139)) | H16: =IF(COLUMN()-2<=Assumptions!$C$139,0,Calculations!$B$10*Assumptions!$C$136/100/(Assumptions!$C$138-Assumptions!$C$139)) | I16: =IF(COLUMN()-2<=Assumptions!$C$139,0,Calculations!$B$10*Assumptions!$C$136/100/(Assumptions!$C$138-Assumptions!$C$139)) | ... K16: =IF(COLUMN()-2<=Assumptions!$C$139,0,Calculations!$B$10*Assumptions!$C$136/100/(Assumptions!$C$138-Assumptions!$C$139))
A17: Closing balance | B17: =B13+B14-B15 | C17: =B13+B14-B15 | D17: =B13+B14-B15 | E17: =B13+B14-B15 | F17: =B13+B14-B15 | G17: =B13+B14-B15 | H17: =B13+B14-B15 | I17: =B13+B14-B15 | J17: =B13+B14-B15 | K17: =B13+B14-B15
A18: Interest expense | B18: =(B13+B16)/2*Assumptions!$C$137/100 | C18: =(B13+B16)/2*Assumptions!$C$137/100 | D18: =(B13+B16)/2*Assumptions!$C$137/100 | E18: =(B13+B16)/2*Assumptions!$C$137/100 | F18: =(B13+B16)/2*Assumptions!$C$137/100 | G18: =(B13+B16)/2*Assumptions!$C$137/100 | H18: =(B13+B16)/2*Assumptions!$C$137/100 | I18: =(B13+B16)/2*Assumptions!$C$137/100 | J18: =(B13+B16)/2*Assumptions!$C$137/100 | K18: =(B13+B16)/2*Assumptions!$C$137/100
A19: Total debt service | B19: =B15+B17 | C19: =B15+B17 | D19: =B15+B17 | E19: =B15+B17 | F19: =B15+B17 | G19: =B15+B17 | H19: =B15+B17 | I19: =B15+B17 | J19: =B15+B17 | K19: =B15+B17
A21: TOTAL DEBT
A22: Total opening balance | B22: =B5+B13 | C22: =B5+B13 | D22: =B5+B13 | E22: =B5+B13 | F22: =B5+B13 | G22: =B5+B13 | H22: =B5+B13 | I22: =B5+B13 | J22: =B5+B13 | K22: =B5+B13
A23: Total drawdowns | B23: =B6+B14 | C23: =B6+B14 | D23: =B6+B14 | E23: =B6+B14 | F23: =B6+B14 | G23: =B6+B14 | H23: =B6+B14 | I23: =B6+B14 | J23: =B6+B14 | K23: =B6+B14
A24: Total principal repayment | B24: =B7+B15 | C24: =B7+B15 | D24: =B7+B15 | E24: =B7+B15 | F24: =B7+B15 | G24: =B7+B15 | H24: =B7+B15 | I24: =B7+B15 | J24: =B7+B15 | K24: =B7+B15
A25: Total closing balance | B25: =B8+B16 | C25: =B8+B16 | D25: =B8+B16 | E25: =B8+B16 | F25: =B8+B16 | G25: =B8+B16 | H25: =B8+B16 | I25: =B8+B16 | J25: =B8+B16 | K25: =B8+B16
A26: Total interest expense | B26: =B9+B17 | C26: =B9+B17 | D26: =B9+B17 | E26: =B9+B17 | F26: =B9+B17 | G26: =B9+B17 | H26: =B9+B17 | I26: =B9+B17 | J26: =B9+B17 | K26: =B9+B17
A27: Total debt service | B27: =B11+B18 | C27: =B11+B18 | D27: =B11+B18 | E27: =B11+B18 | F27: =B11+B18 | G27: =B11+B18 | H27: =B11+B18 | I27: =B11+B18 | J27: =B11+B18 | K27: =B11+B18

Sheet P&L Statement
A1: PROFIT & LOSS STATEMENT
A3: Line Item | B3: Year 1 | C3: Year 2 | D3: Year 3 | E3: Year 4 | F3: Year 5 | G3: Year 6 | H3: Year 7 | I3: Year 8 | J3: Year 9 | K3: Year 10
A4: REVENUE
A5: Total Revenue | B5: =Revenue!B15 | C5: =Revenue!B15 | D5: =Revenue!B15 | E5: =Revenue!B15 | F5: =Revenue!B15 | G5: =Revenue!B15 | H5: =Revenue!B15 | I5: =Revenue!B15 | J5: =Revenue!B15 | K5: =Revenue!B15
A7: OPERATING COSTS
A8: Operating Costs | B8: =-'Operating Costs'!B29 | C8: =-'Operating Costs'!B29 | D8: =-'Operating Costs'!B29 | E8: =-'Operating Costs'!B29 | F8: =-'Operating Costs'!B29 | G8: =-'Operating Costs'!B29 | H8: =-'Operating Costs'!B29 | I8: =-'Operating Costs'!B29 | J8: =-'Operating Costs'!B29 | K8: =-'Operating Costs'!B29
A10: EBITDA | B10: =B5+B8 | C10: =B5+B8 | D10: =B5+B8 | E10: =B5+B8 | F10: =B5+B8 | G10: =B5+B8 | H10: =B5+B8 | I10: =B5+B8 | J10: =B5+B8 | K10: =B5+B8
A11: EBITDA Margin (%) | B11: =B10/B5*100 | C11: =B10/B5*100 | D11: =B10/B5*100 | E11: =B10/B5*100 | F11: =B10/B5*100 | G11: =B10/B5*100 | H11: =B10/B5*100 | I11: =B10/B5*100 | J11: =B10/B5*100 | K11: =B10/B5*100
A13: Depreciation | B13: ='CAPEX Schedule'!B11*0.1 | C13: ='CAPEX Schedule'!B11*0.1 | D13: ='CAPEX Schedule'!B11*0.1 | E13: ='CAPEX Schedule'!B11*0.1 | F13: ='CAPEX Schedule'!B11*0.1 | G13: ='CAPEX Schedule'!B11*0.1 | H13: ='CAPEX Schedule'!B11*0.1 | I13: ='CAPEX Schedule'!B11*0.1 | J13: ='CAPEX Schedule'!B11*0.1 | K13: ='CAPEX Schedule'!B11*0.1
A15: EBIT | B15: =B10-B13 | C15: =B10-B13 | D15: =B10-B13 | E15: =B10-B13 | F15: =B10-B13 | G15: =B10-B13 | H15: =B10-B13 | I15: =B10-B13 | J15: =B10-B13 | K15: =B10-B13
A16: EBIT Margin (%) | B16: =B15/B5*100 | C16: =B15/B5*100 | D16: =B15/B5*100 | E16: =B15/B5*100 | F16: =B15/B5*100 | G16: =B15/B5*100 | H16: =B15/B5*100 | I16: =B15/B5*100 | J16: =B15/B5*100 | K16: =B15/B5*100
A18: Interest Expense | B18: =-'Debt Schedule'!B28 | C18: =-'Debt Schedule'!B28 | D18: =-'Debt Schedule'!B28 | E18: =-'Debt Schedule'!B28 | F18: =-'Debt Schedule'!B28 | G18: =-'Debt Schedule'!B28 | H18: =-'Debt Schedule'!B28 | I18: =-'Debt Schedule'!B28 | J18: =-'Debt Schedule'!B28 | K18: =-'Debt Schedule'!B28
A20: EBT (Earnings Before Tax) | B20: =B15+B18 | C20: =B15+B18 | D20: =B15+B18 | E20: =B15+B18 | F20: =B15+B18 | G20: =B15+B18 | H20: =B15+B18 | I20: =B15+B18 | J20: =B15+B18 | K20: =B15+B18
A22: Tax Expense | B22: =IF(B20>0,IF(COLUMN()-2<=Assumptions!$C$146,-B20*Assumptions!$C$148/100,-B20*Assumptions!$C$145/100),0) | C22: =IF(B20>0,IF(COLUMN()-2<=Assumptions!$C$146,-B20*Assumptions!$C$148/100,-B20*Assumptions!$C$145/100),0) | D22: =IF(B20>0,IF(COLUMN()-2<=Assumptions!$C$146,-B20*Assumptions!$C$148/100,-B20*Assumptions!$C$145/100),0) | E22: =IF(B20>0,IF(COLUMN()-2<=Assumptions!$C$146,-B20*Assumptions!$C$148/100,-B20*Assumptions!$C$145/100),0) | F22: =IF(B20>0,IF(COLUMN()-2<=Assumptions!$C$146,-B20*Assumptions!$C$148/100,-B20*Assumptions!$C$145/100),0) | G22: =IF(B20>0,IF(COLUMN()-2<=Assumptions!$C$146,-B20*Assumptions!$C$148/100,-B20*Assumptions!$C$145/100),0) | H22: =IF(B20>0,IF(COLUMN()-2<=Assumptions!$C$146,-B20*Assumptions!$C$148/100,-B20*Assumptions!$C$145/100),0) | I22: =IF(B20>0,IF(COLUMN()-2<=Assumptions!$C$146,-B20*Assumptions!$C$148/100,-B20*Assumptions!$C$145/100),0) | J22: =IF(B20>0,IF(COLUMN()-2<=Assumptions!$C$146,-B20*Assumptions!$C$148/100,-B20*Assumptions!$C$145/100),0) | K22: =IF(B20>0,IF(COLUMN()-2<=Assumptions!$C$146,-B20*Assumptions!$C$148/100,-B20*Assumptions!$C$145/100),0)
A24: NET INCOME | B24: =B20+B23 | C24: =B20+B23 | D24: =B20+B23 | E24: =B20+B23 | F24: =B20+B23 | G24: =B20+B23 | H24: =B20+B23 | I24: =B20+B23 | J24: =B20+B23 | K24: =B20+B23
A25: Net Margin (%) | B25: =B25/B5*100 | C25: =B25/B5*100 | D25: =B25/B5*100 | E25: =B25/B5*100 | F25: =B25/B5*100 | G25: =B25/B5*100 | H25: =B25/B5*100 | I25: =B25/B5*100 | J25: =B25/B5*100 | K25: =B25/B5*100

Sheet Cash Flow
A1: CASH FLOW STATEMENT
A3: Cash Flow Item | B3: Year 1 | C3: Year 2 | D3: Year 3 | E3: Year 4 | F3: Year 5 | G3: Year 6 | H3: Year 7 | I3: Year 8 | J3: Year 9 | K3: Year 10
A4: OPERATING ACTIVITIES
A5: EBITDA | B5: ='P&L Statement'!B10 | C5: ='P&L Statement'!B10 | D5: ='P&L Statement'!B10 | E5: ='P&L Statement'!B10 | F5: ='P&L Statement'!B10 | G5: ='P&L Statement'!B10 | H5: ='P&L Statement'!B10 | I5: ='P&L Statement'!B10 | J5: ='P&L Statement'!B10 | K5: ='P&L Statement'!B10
A6: Tax Paid | B6: ='P&L Statement'!B23 | C6: ='P&L Statement'!B23 | D6: ='P&L Statement'!B23 | E6: ='P&L Statement'!B23 | F6: ='P&L Statement'!B23 | G6: ='P&L Statement'!B23 | H6: ='P&L Statement'!B23 | I6: ='P&L Statement'!B23 | J6: ='P&L Statement'!B23 | K6: ='P&L Statement'!B23
A7: Change in Working Capital | B7: =-Revenue!B15*0.05 | C7: =-Revenue!B15*0.05 | D7: =-Revenue!B15*0.05 | E7: =-Revenue!B15*0.05 | F7: =-Revenue!B15*0.05 | G7: =-Revenue!B15*0.05 | H7: =-Revenue!B15*0.05 | I7: =-Revenue!B15*0.05 | J7: =-Revenue!B15*0.05 | K7: =-Revenue!B15*0.05
A8: Cash Flow from Operations | B8: =SUM(B5:B7) | C8: =SUM(B5:B7) | D8: =SUM(B5:B7) | E8: =SUM(B5:B7) | F8: =SUM(B5:B7) | G8: =SUM(B5:B7) | H8: =SUM(B5:B7) | I8: =SUM(B5:B7) | J8: =SUM(B5:B7) | K8: =SUM(B5:B7)
A10: INVESTING ACTIVITIES
A11: CAPEX | B11: =-'CAPEX Schedule'!B11 | C11: =-'CAPEX Schedule'!B11 | D11: =-'CAPEX Schedule'!B11 | E11: =-'CAPEX Schedule'!B11 | F11: =-'CAPEX Schedule'!B11 | G11: =-'CAPEX Schedule'!B11 | H11: =-'CAPEX Schedule'!B11 | I11: =-'CAPEX Schedule'!B11 | J11: =-'CAPEX Schedule'!B11 | K11: =-'CAPEX Schedule'!B11
A12: Cash Flow from Investing | B12: =B11 | C12: =B11 | D12: =B11 | E12: =B11 | F12: =B11 | G12: =B11 | H12: =B11 | I12: =B11 | J12: =B11 | K12: =B11
A14: FINANCING ACTIVITIES
A15: Equity Injection | B15: =IF(COLUMN()=2,Calculations!$B$10*Assumptions!$C$125/100,0) | C15: =IF(COLUMN()=2,Calculations!$B$10*Assumptions!$C$125/100,0) | D15: =IF(COLUMN()=2,Calculations!$B$10*Assumptions!$C$125/100,0) | E15: =IF(COLUMN()=2,Calculations!$B$10*Assumptions!$C$125/100,0) | F15: =IF(COLUMN()=2,Calculations!$B$10*Assumptions!$C$125/100,0) | G15: =IF(COLUMN()=2,Calculations!$B$10*Assumptions!$C$125/100,0) | H15: =IF(COLUMN()=2,Calculations!$B$10*Assumptions!$C$125/100,0) | I15: =IF(COLUMN()=2,Calculations!$B$10*Assumptions!$C$125/100,0) | ... K15: =IF(COLUMN()=2,Calculations!$B$10*Assumptions!$C$125/100,0)
A16: Grant Received | B16: =IF(COLUMN()=2,Assumptions!$C$142,0) | C16: =IF(COLUMN()=2,Assumptions!$C$142,0) | D16: =IF(COLUMN()=2,Assumptions!$C$142,0) | E16: =IF(COLUMN()=2,Assumptions!$C$142,0) | F16: =IF(COLUMN()=2,Assumptions!$C$142,0) | G16: =IF(COLUMN()=2,Assumptions!$C$142,0) | H16: =IF(COLUMN()=2,Assumptions!$C$142,0) | I16: =IF(COLUMN()=2,Assumptions!$C$142,0) | ... K16: =IF(COLUMN()=2,Assumptions!$C$142,0)
A17: Debt Drawdown | B17: ='Debt Schedule'!B24 | C17: ='Debt Schedule'!B24 | D17: ='Debt Schedule'!B24 | E17: ='Debt Schedule'!B24 | F17: ='Debt Schedule'!B24 | G17: ='Debt Schedule'!B24 | H17: ='Debt Schedule'!B24 | I17: ='Debt Schedule'!B24 | J17: ='Debt Schedule'!B24 | K17: ='Debt Schedule'!B24
A18: Debt Repayment | B18: =-'Debt Schedule'!B25 | C18: =-'Debt Schedule'!B25 | D18: =-'Debt Schedule'!B25 | E18: =-'Debt Schedule'!B25 | F18: =-'Debt Schedule'!B25 | G18: =-'Debt Schedule'!B25 | H18: =-'Debt Schedule'!B25 | I18: =-'Debt Schedule'!B25 | J18: =-'Debt Schedule'!B25 | K18: =-'Debt Schedule'!B25
A19: Interest Paid | B19: =-'Debt Schedule'!B28 | C19: =-'Debt Schedule'!B28 | D19: =-'Debt Schedule'!B28 | E19: =-'Debt Schedule'!B28 | F19: =-'Debt Schedule'!B28 | G19: =-'Debt Schedule'!B28 | H19: =-'Debt Schedule'!B28 | I19: =-'Debt Schedule'!B28 | J19: =-'Debt Schedule'!B28 | K19: =-'Debt Schedule'!B28
A20: Cash Flow from Financing | B20: =SUM(B15:B19) | C20: =SUM(B15:B19) | D20: =SUM(B15:B19) | E20: =SUM(B15:B19) | F20: =SUM(B15:B19) | G20: =SUM(B15:B19) | H20: =SUM(B15:B19) | I20: =SUM(B15:B19) | J20: =SUM(B15:B19) | K20: =SUM(B15:B19)
A22: NET CASH FLOW | B22: =B8+B12+B20 | C22: =B8+B12+B20 | D22: =B8+B12+B20 | E22: =B8+B12+B20 | F22: =B8+B12+B20 | G22: =B8+B12+B20 | H22: =B8+B12+B20 | I22: =B8+B12+B20 | J22: =B8+B12+B20 | K22: =B8+B12+B20
A24: Opening Cash | B24: =IF(COLUMN()=2,0,OFFSET(B24,0,-1)) | C24: =IF(COLUMN()=2,0,OFFSET(B24,0,-1)) | D24: =IF(COLUMN()=2,0,OFFSET(B24,0,-1)) | E24: =IF(COLUMN()=2,0,OFFSET(B24,0,-1)) | F24: =IF(COLUMN()=2,0,OFFSET(B24,0,-1)) | G24: =IF(COLUMN()=2,0,OFFSET(B24,0,-1)) | H24: =IF(COLUMN()=2,0,OFFSET(B24,0,-1)) | I24: =IF(COLUMN()=2,0,OFFSET(B24,0,-1)) | J24: =IF(COLUMN()=2,0,OFFSET(B24,0,-1)) | K24: =IF(COLUMN()=2,0,OFFSET(B24,0,-1))
A25: Closing Cash | B25: =B23+B22 | C25: =B23+B22 | D25: =B23+B22 | E25: =B23+B22 | F25: =B23+B22 | G25: =B23+B22 | H25: =B23+B22 | I25: =B23+B22 | J25: =B23+B22 | K25: =B23+B22

Sheet Returns Analysis
A1: RETURNS ANALYSIS & KEY METRICS
A3: PROJECT RETURNS
A4: Project IRR (%) | C4: =IRR('Cash Flow'!B22:L22)*100 | D4: %
A5: Equity IRR (%) | C5: =IRR('Cash Flow'!B20:L20)*100 | D5: %
A6: NPV @ 12% (XAF) | C6: =NPV(Assumptions!$C$156/100,'Cash Flow'!C22:L22)+'Cash Flow'!B22 | D6: XAF
A7: Payback Period (years) | C7: 5.5 | D7: years
A9: PROFITABILITY METRICS
A10: Average EBITDA Margin (%) | C10: =AVERAGE('P&L Statement'!B11:L11) | D10: %
A11: Average Net Margin (%) | C11: =AVERAGE('P&L Statement'!B26:L26) | D11: %
A12: Peak Revenue (XAF) | C12: =MAX(Revenue!B15:L15) | D12: XAF
A13: Peak EBITDA (XAF) | C13: =MAX('P&L Statement'!B10:L10) | D13: XAF
A15: DEBT SERVICE COVERAGE
A16: Min DSCR | C16: =MIN(B40:L40) | D16: x
A17: Avg DSCR | C17: =AVERAGE(B40:L40) | D17: x
A19: LEVERAGE RATIOS
A20: Debt to Equity (Year 1) | C20: ='Debt Schedule'!B27/('CAPEX Schedule'!B11*Assumptions!$C$125/100) | D20: x
A21: Avg Interest Coverage | C21: =AVERAGE(B45:L45) | D21: x
A23: VALUATION METRICS
A24: Terminal Value (XAF) | C24: ='P&L Statement'!L25*(1+Assumptions!$C$157/100)/(Assumptions!$C$156/100-Assumptions!$C$157/100) | D24: XAF
A25: Enterprise Value (XAF) | C25: =B6+B23 | D25: XAF
A26: Equity Value (XAF) | C26: =B24-'Debt Schedule'!L27 | D26: XAF
A29: DSCR BY YEAR:
A30: Year | B30: 1 | C30: 2 | D30: 3 | E30: 4 | F30: 5 | G30: 6 | H30: 7 | I30: 8 | J30: 9 | K30: 10
A31: DSCR | B31: =('P&L Statement'!B10+'P&L Statement'!B23-'CAPEX Schedule'!B11)/'Debt Schedule'!B29 | C31: =('P&L Statement'!C10+'P&L Statement'!C23-'CAPEX Schedule'!C11)/'Debt Schedule'!C29 | D31: =('P&L Statement'!D10+'P&L Statement'!D23-'CAPEX Schedule'!D11)/'Debt Schedule'!D29 | E31: =('P&L Statement'!E10+'P&L Statement'!E23-'CAPEX Schedule'!E11)/'Debt Schedule'!E29 | F31: =('P&L Statement'!F10+'P&L Statement'!F23-'CAPEX Schedule'!F11)/'Debt Schedule'!F29 | G31: =('P&L Statement'!G10+'P&L Statement'!G23-'CAPEX Schedule'!G11)/'Debt Schedule'!G29 | H31: =('P&L Statement'!H10+'P&L Statement'!H23-'CAPEX Schedule'!H11)/'Debt Schedule'!H29 | I31: =('P&L Statement'!I10+'P&L Statement'!I23-'CAPEX Schedule'!I11)/'Debt Schedule'!I29 | ... K31: =('P&L Statement'!K10+'P&L Statement'!K23-'CAPEX Schedule'!K11)/'Debt Schedule'!K29
A33: Interest Coverage | B33: =IF('Debt Schedule'!B28<>0,'P&L Statement'!B15/'Debt Schedule'!B28,0) | C33: =IF('Debt Schedule'!C28<>0,'P&L Statement'!C15/'Debt Schedule'!C28,0) | D33: =IF('Debt Schedule'!D28<>0,'P&L Statement'!D15/'Debt Schedule'!D28,0) | E33: =IF('Debt Schedule'!E28<>0,'P&L Statement'!E15/'Debt Schedule'!E28,0) | F33: =IF('Debt Schedule'!F28<>0,'P&L Statement'!F15/'Debt Schedule'!F28,0) | G33: =IF('Debt Schedule'!G28<>0,'P&L Statement'!G15/'Debt Schedule'!G28,0) | H33: =IF('Debt Schedule'!H28<>0,'P&L Statement'!H15/'Debt Schedule'!H28,0) | I33: =IF('Debt Schedule'!I28<>0,'P&L Statement'!I15/'Debt Schedule'!I28,0) | ... K33: =IF('Debt Schedule'!K28<>0,'P&L Statement'!K15/'Debt Schedule'!K28,0)

Sheet Development Impact
A1: DEVELOPMENT IMPACT METRICS
A3: Impact Metric | B3: Year 1 | C3: Year 2 | D3: Year 3 | E3: Year 4 | F3: Year 5 | G3: Year 6 | H3: Year 7 | I3: Year 8 | J3: Year 9 | K3: Year 10
A4: FARMER IMPACT
A5: Number of Farmers | B5: =IF(COLUMN()=2,Assumptions!$C$19,IF(COLUMN()=3,Assumptions!$C$20,Assumptions!$C$21)) | C5: =IF(COLUMN()=2,Assumptions!$C$19,IF(COLUMN()=3,Assumptions!$C$20,Assumptions!$C$21)) | D5: =IF(COLUMN()=2,Assumptions!$C$19,IF(COLUMN()=3,Assumptions!$C$20,Assumptions!$C$21)) | E5: =IF(COLUMN()=2,Assumptions!$C$19,IF(COLUMN()=3,Assumptions!$C$20,Assumptions!$C$21)) | F5: =IF(COLUMN()=2,Assumptions!$C$19,IF(COLUMN()=3,Assumptions!$C$20,Assumptions!$C$21)) | G5: =IF(COLUMN()=2,Assumptions!$C$19,IF(COLUMN()=3,Assumptions!$C$20,Assumptions!$C$21)) | H5: =IF(COLUMN()=2,Assumptions!$C$19,IF(COLUMN()=3,Assumptions!$C$20,Assumptions!$C$21)) | I5: =IF(COLUMN()=2,Assumptions!$C$19,IF(COLUMN()=3,Assumptions!$C$20,Assumptions!$C$21)) | ... K5: =IF(COLUMN()=2,Assumptions!$C$19,IF(COLUMN()=3,Assumptions!$C$20,Assumptions!$C$21))
A6: Hectares Supported | B6: =B5*Assumptions!$C$22 | C6: =B5*Assumptions!$C$22 | D6: =B5*Assumptions!$C$22 | E6: =B5*Assumptions!$C$22 | F6: =B5*Assumptions!$C$22 | G6: =B5*Assumptions!$C$22 | H6: =B5*Assumptions!$C$22 | I6: =B5*Assumptions!$C$22 | J6: =B5*Assumptions!$C$22 | K6: =B5*Assumptions!$C$22
A7: Avg Farmer Income (XAF) | B7: =Assumptions!$C$22*Assumptions!$C$23*Assumptions!$C$48*(1+Assumptions!$C$48/100)^(COLUMN()-2) | C7: =Assumptions!$C$22*Assumptions!$C$23*Assumptions!$C$48*(1+Assumptions!$C$48/100)^(COLUMN()-2) | D7: =Assumptions!$C$22*Assumptions!$C$23*Assumptions!$C$48*(1+Assumptions!$C$48/100)^(COLUMN()-2) | E7: =Assumptions!$C$22*Assumptions!$C$23*Assumptions!$C$48*(1+Assumptions!$C$48/100)^(COLUMN()-2) | F7: =Assumptions!$C$22*Assumptions!$C$23*Assumptions!$C$48*(1+Assumptions!$C$48/100)^(COLUMN()-2) | G7: =Assumptions!$C$22*Assumptions!$C$23*Assumptions!$C$48*(1+Assumptions!$C$48/100)^(COLUMN()-2) | H7: =Assumptions!$C$22*Assumptions!$C$23*Assumptions!$C$48*(1+Assumptions!$C$48/100)^(COLUMN()-2) | I7: =Assumptions!$C$22*Assumptions!$C$23*Assumptions!$C$48*(1+Assumptions!$C$48/100)^(COLUMN()-2) | ... K7: =Assumptions!$C$22*Assumptions!$C$23*Assumptions!$C$48*(1+Assumptions!$C$48/100)^(COLUMN()-2)
A8: Income Improvement (%) | B8: =(Assumptions!$C$23-Assumptions!$C$24)/Assumptions!$C$24*100 | C8: =(Assumptions!$C$23-Assumptions!$C$24)/Assumptions!$C$24*100 | D8: =(Assumptions!$C$23-Assumptions!$C$24)/Assumptions!$C$24*100 | E8: =(Assumptions!$C$23-Assumptions!$C$24)/Assumptions!$C$24*100 | F8: =(Assumptions!$C$23-Assumptions!$C$24)/Assumptions!$C$24*100 | G8: =(Assumptions!$C$23-Assumptions!$C$24)/Assumptions!$C$24*100 | H8: =(Assumptions!$C$23-Assumptions!$C$24)/Assumptions!$C$24*100 | I8: =(Assumptions!$C$23-Assumptions!$C$24)/Assumptions!$C$24*100 | ... K8: =(Assumptions!$C$23-Assumptions!$C$24)/Assumptions!$C$24*100
A9: Total Farmer Payments (XAF) | B9: =B5*B7 | C9: =B5*B7 | D9: =B5*B7 | E9: =B5*B7 | F9: =B5*B7 | G9: =B5*B7 | H9: =B5*B7 | I9: =B5*B7 | J9: =B5*B7 | K9: =B5*B7
A11: JOB CREATION
A12: Direct Jobs - Seed Production | B12: =Assumptions!$C$14*0.5 | C12: =Assumptions!$C$14*0.5 | D12: =Assumptions!$C$14*0.5 | E12: =Assumptions!$C$14*0.5 | F12: =Assumptions!$C$14*0.5 | G12: =Assumptions!$C$14*0.5 | H12: =Assumptions!$C$14*0.5 | I12: =Assumptions!$C$14*0.5 | ... K12: =Assumptions!$C$14*0.5
A13: Direct Jobs - Processing | B13: =Revenue!B11*0.02 | C13: =Revenue!B11*0.02 | D13: =Revenue!B11*0.02 | E13: =Revenue!B11*0.02 | F13: =Revenue!B11*0.02 | G13: =Revenue!B11*0.02 | H13: =Revenue!B11*0.02 | I13: =Revenue!B11*0.02 | J13: =Revenue!B11*0.02 | K13: =Revenue!B11*0.02
A14: Direct Jobs - Admin & Support | B14: 20 | C14: 20 | D14: 20 | E14: 20 | F14: 20 | G14: 20 | H14: 20 | I14: 20 | J14: 20 | K14: 20
A15: Total Direct Jobs | B15: =SUM(B12:B14) | C15: =SUM(B12:B14) | D15: =SUM(B12:B14) | E15: =SUM(B12:B14) | F15: =SUM(B12:B14) | G15: =SUM(B12:B14) | H15: =SUM(B12:B14) | I15: =SUM(B12:B14) | J15: =SUM(B12:B14) | K15: =SUM(B12:B14)
A16: Indirect Jobs (multiplier 3x) | B16: =B15*3 | C16: =B15*3 | D16: =B15*3 | E16: =B15*3 | F16: =B15*3 | G16: =B15*3 | H16: =B15*3 | I16: =B15*3 | J16: =B15*3 | K16: =B15*3
A17: Total Jobs Created | B17: =B15+B16 | C17: =B15+B16 | D17: =B15+B16 | E17: =B15+B16 | F17: =B15+B16 | G17: =B15+B16 | H17: =B15+B16 | I17: =B15+B16 | J17: =B15+B16 | K17: =B15+B16
A19: WOMEN PARTICIPATION
A20: Women Farmers (%) | B20: 40 | C20: 40 | D20: 40 | E20: 40 | F20: 40 | G20: 40 | H20: 40 | I20: 40 | J20: 40 | K20: 40
A21: Women Employees (%) | B21: 35 | C21: 35 | D21: 35 | E21: 35 | F21: 35 | G21: 35 | H21: 35 | I21: 35 | J21: 35 | K21: 35
A23: PRODUCTION IMPACT
A24: Total Production (tonnes) | B24: =B5*Assumptions!$C$22*Assumptions!$C$23 | C24: =B5*Assumptions!$C$22*Assumptions!$C$23 | D24: =B5*Assumptions!$C$22*Assumptions!$C$23 | E24: =B5*Assumptions!$C$22*Assumptions!$C$23 | F24: =B5*Assumptions!$C$22*Assumptions!$C$23 | G24: =B5*Assumptions!$C$22*Assumptions!$C$23 | H24: =B5*Assumptions!$C$22*Assumptions!$C$23 | I24: =B5*Assumptions!$C$22*Assumptions!$C$23 | J24: =B5*Assumptions!$C$22*Assumptions!$C$23 | K24: =B5*Assumptions!$C$22*Assumptions!$C$23
A25: Production Increase vs Baseline | B25: =B24*(1-Assumptions!$C$24/Assumptions!$C$23) | C25: =B24*(1-Assumptions!$C$24/Assumptions!$C$23) | D25: =B24*(1-Assumptions!$C$24/Assumptions!$C$23) | E25: =B24*(1-Assumptions!$C$24/Assumptions!$C$23) | F25: =B24*(1-Assumptions!$C$24/Assumptions!$C$23) | G25: =B24*(1-Assumptions!$C$24/Assumptions!$C$23) | H25: =B24*(1-Assumptions!$C$24/Assumptions!$C$23) | I25: =B24*(1-Assumptions!$C$24/Assumptions!$C$23) | J25: =B24*(1-Assumptions!$C$24/Assumptions!$C$23) | K25: =B24*(1-Assumptions!$C$24/Assumptions!$C$23)
A26: Import Substitution Value (XAF) | B26: =B24*Assumptions!$C$51*1000 | C26: =B24*Assumptions!$C$51*1000 | D26: =B24*Assumptions!$C$51*1000 | E26: =B24*Assumptions!$C$51*1000 | F26: =B24*Assumptions!$C$51*1000 | G26: =B24*Assumptions!$C$51*1000 | H26: =B24*Assumptions!$C$51*1000 | I26: =B24*Assumptions!$C$51*1000 | J26: =B24*Assumptions!$C$51*1000 | K26: =B24*Assumptions!$C$51*1000
A28: ECONOMIC IMPACT
A29: Tax Revenue Generated (XAF) | B29: =-'P&L Statement'!B23 | C29: =-'P&L Statement'!B23 | D29: =-'P&L Statement'!B23 | E29: =-'P&L Statement'!B23 | F29: =-'P&L Statement'!B23 | G29: =-'P&L Statement'!B23 | H29: =-'P&L Statement'!B23 | I29: =-'P&L Statement'!B23 | J29: =-'P&L Statement'!B23 | K29: =-'P&L Statement'!B23
A30: Local Value Added (XAF) | B30: ='Operating Costs'!B29+B28 | C30: ='Operating Costs'!B29+B28 | D30: ='Operating Costs'!B29+B28 | E30: ='Operating Costs'!B29+B28 | F30: ='Operating Costs'!B29+B28 | G30: ='Operating Costs'!B29+B28 | H30: ='Operating Costs'!B29+B28 | I30: ='Operating Costs'!B29+B28 | J30: ='Operating Costs'!B29+B28 | K30: ='Operating Costs'!B29+B28
A32: CUMULATIVE IMPACT (to date)
A33: Cumulative Farmers Supported | B33: =SUM($B$5:B5) | C33: =SUM($B$5:B5) | D33: =SUM($B$5:B5) | E33: =SUM($B$5:B5) | F33: =SUM($B$5:B5) | G33: =SUM($B$5:B5) | H33: =SUM($B$5:B5) | I33: =SUM($B$5:B5) | J33: =SUM($B$5:B5) | K33: =SUM($B$5:B5)
A34: Cumulative Jobs Created | B34: =SUM($B$17:B17) | C34: =SUM($B$17:B17) | D34: =SUM($B$17:B17) | E34: =SUM($B$17:B17) | F34: =SUM($B$17:B17) | G34: =SUM($B$17:B17) | H34: =SUM($B$17:B17) | I34: =SUM($B$17:B17) | J34: =SUM($B$17:B17) | K34: =SUM($B$17:B17)
A35: Cumulative Tax Revenue (XAF) | B35: =SUM($B$28:B28) | C35: =SUM($B$28:B28) | D35: =SUM($B$28:B28) | E35: =SUM($B$28:B28) | F35: =SUM($B$28:B28) | G35: =SUM($B$28:B28) | H35: =SUM($B$28:B28) | I35: =SUM($B$28:B28) | J35: =SUM($B$28:B28) | K35: =SUM($B$28:B28)

Sheet Sensitivity Analysis
A1: SENSITIVITY ANALYSIS
A3: KEY ASSUMPTIONS TO TEST:
A4: 1. Yield per hectare (Assumptions!C23): ±20%
A5: 2. Product pricing (Assumptions!C51): ±15%
A6: 3. CAPEX costs (Calculations!B10): ±15%
A7: 4. Operating costs: ±10%
A8: 5. Capacity utilization (Assumptions!C35-37): ±10%
A9: 6. Interest rates (Assumptions!C129): ±200 bps
A10: 7. Ramp-up timing: ±6 months
A13: SCENARIO SUMMARY
A14: Scenario | B14: Project IRR | C14: Equity IRR | D14: NPV (XAF M) | E14: Min DSCR | F14: Payback
A15: Base Case | B15: ='Returns Analysis'!C4 | C15: ='Returns Analysis'!C5 | D15: ='Returns Analysis'!C6/1000000 | E15: ='Returns Analysis'!C14 | F15: ='Returns Analysis'!C7
A16: Downside (-20% yield, -15% price, +15% CAPEX) | B16: TBD | C16: TBD | D16: TBD | E16: TBD | F16: TBD
A17: Upside (+10% yield, +10% price, -5% CAPEX) | B17: TBD | C17: TBD | D17: TBD | E17: TBD | F17: TBD

Sheet Documentation
A1: MODEL DOCUMENTATION & USER GUIDE
A4: MODEL OVERVIEW
A6: Model Name: | B6: DFI Investment Proposal - Agricultural Processing
A7: Version: | B7: 1.0
A8: Created: | B8: January 24, 2026
A9: Currency: | B9: XAF (Central African Franc)
A10: Time Horizon: | B10: 10 years
A12: WORKSHEET GUIDE
A14: Dashboard | B14: Executive summary with key metrics
A15: Assumptions | B15: ALL INPUTS - edit blue cells only
A16: Calculations | B16: Derived values (auto-calculated)
A17: Revenue | B17: 10-year revenue projections
A18: Operating Costs | B18: Detailed OPEX by category
A19: CAPEX Schedule | B19: Capital expenditure by phase
A20: Debt Schedule | B20: Debt amortization and service
A21: P&L Statement | B21: Profit & Loss (Income Statement)
A22: Cash Flow | B22: Operating, Investing, Financing cash flows
A23: Returns Analysis | B23: IRR, NPV, DSCR, key metrics
A24: Development Impact | B24: Farmer, job, production metrics
A25: Sensitivity Analysis | B25: Scenario testing
A26: Documentation | B26: This guide
A28: HOW TO USE
A30: 1. Input Data | B30: Go to Assumptions sheet, edit BLUE cells only
A31: 2. Review Outputs | B31: Check Dashboard, P&L, Cash Flow, Returns Analysis
A32: 3. Test Scenarios | B32: Change assumptions to see impact on returns
A33: 4. Validate | B33: Ensure DSCR > 1.2, IRR > hurdle rate, NPV > 0
A35: COLOR CODING
A37: Blue cells | B37: USER INPUTS - edit these
A38: Yellow cells | B38: CALCULATIONS - do not edit
A39: Green headers | B39: Section headers
A40: Gray cells | B40: Column/row headers
A42: IMPORTANT NOTES
A44: • Only edit blue cells in Assumptions sheet
A45: • All other cells contain formulas - do not edit
A46: • Save dated versions (v1.0_2026-01-24, etc.)
A47: • Document assumption sources and dates
A48: • Review all outputs before sharing with investors
A50: VALIDATION CHECKLIST
A52: ☐ All assumptions inputted and validated
A53: ☐ CAPEX costs verified with quotes
...
