Workbook

Sheet Dashboard
A1: SANTA FRESH - EXECUTIVE DASHBOARD
A3: PROJECT OVERVIEW
A4: Project Name | B4: EIC Integrated Potato Value Chain
A5: Location | B5: Santa, Northwest Region, Cameroon
A6: Model Horizon | B6: =Assumptions!B7&" years"
A8: FINANCIAL SUMMARY
A9: Total CAPEX | B9: =Calculations!B9 | C9: XAF
A10: Average Annual Revenue (Years 1-10) | B10: =AVERAGE(Revenue!C7:L7) | C10: XAF
A11: Average EBITDA (Years 1-10) | B11: =AVERAGE('P&L Statement'!C7:L7) | C11: XAF
A12: EBITDA Margin (%) | B12: =B13/B12*100 | C12: %
A14: INVESTMENT RETURNS
A15: Project IRR | B15: ='Returns Analysis'!B3 | C15: %
A16: Project NPV | B16: ='Returns Analysis'!B4 | C16: XAF
A17: Equity IRR | B17: ='Returns Analysis'!B5 | C17: %
A18: Average DSCR | B18: ='Returns Analysis'!B6 | C18: x
A20: DEVELOPMENT IMPACT
A21: Total Jobs Created | B21: ='Development Impact'!B10 | C21: Jobs
A22: Farmers Supported | B22: ='Development Impact'!B13 | C22: Farmers
A23: Farmer Income Increase | B23: ='Development Impact'!B18 | C23: %
A24: Import Substitution Value | B24: ='Development Impact'!B24 | C24: XAF/year

Sheet Assumptions
A1: SANTA FRESH POTATO VALUE CHAIN - FINANCIAL MODEL ASSUMPTIONS
A2: INSTRUCTIONS: BLUE cells = Your inputs (editable) | YELLOW cells = Auto-calculated | GREEN cells = Scenario toggles
A4: Parameter | B4: Value | C4: Unit | D4: Notes
A5: A. PROJECT TIMELINE & PHASING
A6: Model start year | C6: Year | D6: e.g., 2026
A7: Model horizon (years) | C7: Years | D7: e.g., 10
A8: Construction start date | C8: Date | D8: e.g., Q2 2026
A9: Phase 1 duration (months) | C9: Months | D9: Seed/farm/fresh-pack/storage foundation
A10: Phase 2 duration (months) | C10: Months | D10: Frozen line + Douala depot
A11: Phase 3 duration (months) | C11: Months | D11: 3 additional depots
A12: Operations start - Fresh-pack | C12: Date | D12: e.g., Q1 2027
A13: Operations start - Frozen line | C13: Date | D13: e.g., Q3 2028
A15: B. REVENUE STREAMS & PRODUCTS
A16: B1: Fresh-Pack Table Potatoes
A17: Annual target volume - Year 1 | C17: Tonnes
A18: Annual target volume - Year 2 | C18: Tonnes
A19: Annual target volume - Year 3+ | C19: Tonnes
A20: Selling price (XAF/kg) | C20: XAF/kg
A21: Price escalation | C21: %/year
A22: Customer payment terms | C22: Days | D22: Weighted average across segments
A24: B2: Frozen French Fries
A25: Annual target volume - Year 1 | C25: Tonnes
A26: Annual target volume - Year 2 | C26: Tonnes
A27: Annual target volume - Year 3+ | C27: Tonnes
A28: Selling price (XAF/kg) | C28: XAF/kg
A29: Price escalation | C29: %/year
A30: Customer payment terms | C30: Days
A32: B3: Certified Seed Sales
A33: Annual sales volume | C33: Tonnes | D33: G1 seed sold to external customers
A34: Selling price (XAF/kg) | C34: XAF/kg
A35: Price escalation | C35: %/year
A37: B4: Animal Feed Pellets (Byproduct)
A38: Organic waste generation rate | C38: kg/tonne | D38: Peels + rejects per tonne processed
A39: Feed conversion rate | C39: % | D39: Waste to finished pellets
A40: Feed selling price (XAF/kg) | C40: XAF/kg
A41: Feed price escalation | C41: %/year
A43: B5: Revenue Seasonality (Monthly Distribution)
A44: January revenue | C44: % of annual
A45: February revenue | C45: % of annual
A46: March revenue | C46: % of annual
...

Sheet Calculations
A1: CALCULATIONS - Derived Values
A2: Parameter | B2: Year 0 | C2: Year 1 | D2: Year 2 | E2: Year 3 | F2: Year 4 | G2: Year 5 | H2: Year 6 | I2: Year 7 | J2: Year 8 | K2: Year 9 | L2: Year 10
A3: Model start year | B3: =Assumptions!B6
A4: Calendar year | B4: =$B$3 | C4: =B4+1 | D4: =C4+1 | E4: =D4+1 | F4: =E4+1 | G4: =F4+1 | H4: =G4+1 | I4: =H4+1 | J4: =I4+1 | ... L4: =K4+1
A6: Total CAPEX - Phase 1 | B6: =SUM(Assumptions!B258:B284)
A7: Total CAPEX - Phase 2 | B7: =SUM(Assumptions!B287:B293)
A8: Total CAPEX - Phase 3 | B8: =SUM(Assumptions!B296:B301)
A9: Total CAPEX (all phases) | B9: =SUM(B6:B8)
A11: Fresh-pack annual capacity (tonnes) | B11: =Assumptions!B58*Assumptions!B59*(Assumptions!B60-Assumptions!B61)
A12: Frozen line annual capacity (tonnes) | B12: =Assumptions!B66*Assumptions!B67*(Assumptions!B68-Assumptions!B69)

Sheet Revenue
A1: REVENUE PROJECTIONS
A2: Revenue Stream | B2: Year 0 | C2: Year 1 | D2: Year 2 | E2: Year 3 | F2: Year 4 | G2: Year 5 | H2: Year 6 | I2: Year 7 | J2: Year 8 | K2: Year 9 | L2: Year 10
A3: Fresh-Pack Table Potatoes | B3: 0 | C3: =Assumptions!B17*Assumptions!B20*(1+Assumptions!B21/100)^(1-1)*1000 | D3: =Assumptions!B17*Assumptions!B20*(1+Assumptions!B21/100)^(2-1)*1000 | E3: =Assumptions!B17*Assumptions!B20*(1+Assumptions!B21/100)^(3-1)*1000 | F3: =Assumptions!B17*Assumptions!B20*(1+Assumptions!B21/100)^(4-1)*1000 | G3: =Assumptions!B17*Assumptions!B20*(1+Assumptions!B21/100)^(5-1)*1000 | H3: =Assumptions!B17*Assumptions!B20*(1+Assumptions!B21/100)^(6-1)*1000 | I3: =Assumptions!B17*Assumptions!B20*(1+Assumptions!B21/100)^(7-1)*1000 | J3: =Assumptions!B17*Assumptions!B20*(1+Assumptions!B21/100)^(8-1)*1000 | K3: =Assumptions!B17*Assumptions!B20*(1+Assumptions!B21/100)^(9-1)*1000 | L3: =Assumptions!B17*Assumptions!B20*(1+Assumptions!B21/100)^(10-1)*1000
A4: Frozen French Fries | B4: 0 | C4: =Assumptions!B24*Assumptions!B27*(1+Assumptions!B28/100)^(1-1)*1000 | D4: =Assumptions!B24*Assumptions!B27*(1+Assumptions!B28/100)^(2-1)*1000 | E4: =Assumptions!B24*Assumptions!B27*(1+Assumptions!B28/100)^(3-1)*1000 | F4: =Assumptions!B24*Assumptions!B27*(1+Assumptions!B28/100)^(4-1)*1000 | G4: =Assumptions!B24*Assumptions!B27*(1+Assumptions!B28/100)^(5-1)*1000 | H4: =Assumptions!B24*Assumptions!B27*(1+Assumptions!B28/100)^(6-1)*1000 | I4: =Assumptions!B24*Assumptions!B27*(1+Assumptions!B28/100)^(7-1)*1000 | J4: =Assumptions!B24*Assumptions!B27*(1+Assumptions!B28/100)^(8-1)*1000 | K4: =Assumptions!B24*Assumptions!B27*(1+Assumptions!B28/100)^(9-1)*1000 | L4: =Assumptions!B24*Assumptions!B27*(1+Assumptions!B28/100)^(10-1)*1000
A5: Certified Seed Sales | B5: 0 | C5: =Assumptions!B31*Assumptions!B32*(1+Assumptions!B33/100)^(1-1)*1000 | D5: =Assumptions!B31*Assumptions!B32*(1+Assumptions!B33/100)^(2-1)*1000 | E5: =Assumptions!B31*Assumptions!B32*(1+Assumptions!B33/100)^(3-1)*1000 | F5: =Assumptions!B31*Assumptions!B32*(1+Assumptions!B33/100)^(4-1)*1000 | G5: =Assumptions!B31*Assumptions!B32*(1+Assumptions!B33/100)^(5-1)*1000 | H5: =Assumptions!B31*Assumptions!B32*(1+Assumptions!B33/100)^(6-1)*1000 | I5: =Assumptions!B31*Assumptions!B32*(1+Assumptions!B33/100)^(7-1)*1000 | J5: =Assumptions!B31*Assumptions!B32*(1+Assumptions!B33/100)^(8-1)*1000 | K5: =Assumptions!B31*Assumptions!B32*(1+Assumptions!B33/100)^(9-1)*1000 | L5: =Assumptions!B31*Assumptions!B32*(1+Assumptions!B33/100)^(10-1)*1000
A6: Animal Feed Pellets | B6: 0 | C6: =(Assumptions!B17+Assumptions!B24)*Assumptions!B35/1000*Assumptions!B36/100*Assumptions!B37*(1+Assumptions!B38/100)^(1-1)*1000 | D6: =(Assumptions!B17+Assumptions!B24)*Assumptions!B35/1000*Assumptions!B36/100*Assumptions!B37*(1+Assumptions!B38/100)^(2-1)*1000 | E6: =(Assumptions!B17+Assumptions!B24)*Assumptions!B35/1000*Assumptions!B36/100*Assumptions!B37*(1+Assumptions!B38/100)^(3-1)*1000 | F6: =(Assumptions!B17+Assumptions!B24)*Assumptions!B35/1000*Assumptions!B36/100*Assumptions!B37*(1+Assumptions!B38/100)^(4-1)*1000 | G6: =(Assumptions!B17+Assumptions!B24)*Assumptions!B35/1000*Assumptions!B36/100*Assumptions!B37*(1+Assumptions!B38/100)^(5-1)*1000 | H6: =(Assumptions!B17+Assumptions!B24)*Assumptions!B35/1000*Assumptions!B36/100*Assumptions!B37*(1+Assumptions!B38/100)^(6-1)*1000 | I6: =(Assumptions!B17+Assumptions!B24)*Assumptions!B35/1000*Assumptions!B36/100*Assumptions!B37*(1+Assumptions!B38/100)^(7-1)*1000 | J6: =(Assumptions!B17+Assumptions!B24)*Assumptions!B35/1000*Assumptions!B36/100*Assumptions!B37*(1+Assumptions!B38/100)^(8-1)*1000 | K6: =(Assumptions!B17+Assumptions!B24)*Assumptions!B35/1000*Assumptions!B36/100*Assumptions!B37*(1+Assumptions!B38/100)^(9-1)*1000 | L6: =(Assumptions!B17+Assumptions!B24)*Assumptions!B35/1000*Assumptions!B36/100*Assumptions!B37*(1+Assumptions!B38/100)^(10-1)*1000
A7: TOTAL REVENUE | B7: =SUM(B3:B6) | C7: =SUM(C3:C6) | D7: =SUM(D3:D6) | E7: =SUM(E3:E6) | F7: =SUM(F3:F6) | G7: =SUM(G3:G6) | H7: =SUM(H3:H6) | I7: =SUM(I3:I6) | ... L7: =SUM(L3:L6)

Sheet Operating Costs
A1: OPERATING COSTS
A2: Cost Category | B2: Year 0 | C2: Year 1 | D2: Year 2 | E2: Year 3 | F2: Year 4 | G2: Year 5 | H2: Year 6 | I2: Year 7 | J2: Year 8 | K2: Year 9 | L2: Year 10
A3: Raw Materials - Ware Potatoes | B3: 0 | C3: =(Assumptions!B17+Assumptions!B24)*Assumptions!B83*(1+Assumptions!B85/100)^(1-1)*1000 | D3: =(Assumptions!B17+Assumptions!B24)*Assumptions!B83*(1+Assumptions!B85/100)^(2-1)*1000 | E3: =(Assumptions!B17+Assumptions!B24)*Assumptions!B83*(1+Assumptions!B85/100)^(3-1)*1000 | F3: =(Assumptions!B17+Assumptions!B24)*Assumptions!B83*(1+Assumptions!B85/100)^(4-1)*1000 | G3: =(Assumptions!B17+Assumptions!B24)*Assumptions!B83*(1+Assumptions!B85/100)^(5-1)*1000 | H3: =(Assumptions!B17+Assumptions!B24)*Assumptions!B83*(1+Assumptions!B85/100)^(6-1)*1000 | I3: =(Assumptions!B17+Assumptions!B24)*Assumptions!B83*(1+Assumptions!B85/100)^(7-1)*1000 | J3: =(Assumptions!B17+Assumptions!B24)*Assumptions!B83*(1+Assumptions!B85/100)^(8-1)*1000 | K3: =(Assumptions!B17+Assumptions!B24)*Assumptions!B83*(1+Assumptions!B85/100)^(9-1)*1000 | L3: =(Assumptions!B17+Assumptions!B24)*Assumptions!B83*(1+Assumptions!B85/100)^(10-1)*1000
A4: Labor - All Departments | B4: 0 | C4: =(Assumptions!B155+Assumptions!B158+Assumptions!B161+Assumptions!B164+Assumptions!B167+Assumptions!B170+Assumptions!B173)*12*(1+Assumptions!B175/100)^(1-1) | D4: =(Assumptions!B155+Assumptions!B158+Assumptions!B161+Assumptions!B164+Assumptions!B167+Assumptions!B170+Assumptions!B173)*12*(1+Assumptions!B175/100)^(2-1) | E4: =(Assumptions!B155+Assumptions!B158+Assumptions!B161+Assumptions!B164+Assumptions!B167+Assumptions!B170+Assumptions!B173)*12*(1+Assumptions!B175/100)^(3-1) | F4: =(Assumptions!B155+Assumptions!B158+Assumptions!B161+Assumptions!B164+Assumptions!B167+Assumptions!B170+Assumptions!B173)*12*(1+Assumptions!B175/100)^(4-1) | G4: =(Assumptions!B155+Assumptions!B158+Assumptions!B161+Assumptions!B164+Assumptions!B167+Assumptions!B170+Assumptions!B173)*12*(1+Assumptions!B175/100)^(5-1) | H4: =(Assumptions!B155+Assumptions!B158+Assumptions!B161+Assumptions!B164+Assumptions!B167+Assumptions!B170+Assumptions!B173)*12*(1+Assumptions!B175/100)^(6-1) | I4: =(Assumptions!B155+Assumptions!B158+Assumptions!B161+Assumptions!B164+Assumptions!B167+Assumptions!B170+Assumptions!B173)*12*(1+Assumptions!B175/100)^(7-1) | J4: =(Assumptions!B155+Assumptions!B158+Assumptions!B161+Assumptions!B164+Assumptions!B167+Assumptions!B170+Assumptions!B173)*12*(1+Assumptions!B175/100)^(8-1) | K4: =(Assumptions!B155+Assumptions!B158+Assumptions!B161+Assumptions!B164+Assumptions!B167+Assumptions!B170+Assumptions!B173)*12*(1+Assumptions!B175/100)^(9-1) | L4: =(Assumptions!B155+Assumptions!B158+Assumptions!B161+Assumptions!B164+Assumptions!B167+Assumptions!B170+Assumptions!B173)*12*(1+Assumptions!B175/100)^(10-1)
A5: Utilities (Electricity, Water, Diesel) | B5: 0 | C5: =(Assumptions!B178*Assumptions!B179+Assumptions!B180*Assumptions!B181*Assumptions!B182+Assumptions!B186*Assumptions!B187+Assumptions!B190*Assumptions!B191)*(1+Assumptions!B194/100)^(1-1) | D5: =(Assumptions!B178*Assumptions!B179+Assumptions!B180*Assumptions!B181*Assumptions!B182+Assumptions!B186*Assumptions!B187+Assumptions!B190*Assumptions!B191)*(1+Assumptions!B194/100)^(2-1) | E5: =(Assumptions!B178*Assumptions!B179+Assumptions!B180*Assumptions!B181*Assumptions!B182+Assumptions!B186*Assumptions!B187+Assumptions!B190*Assumptions!B191)*(1+Assumptions!B194/100)^(3-1) | F5: =(Assumptions!B178*Assumptions!B179+Assumptions!B180*Assumptions!B181*Assumptions!B182+Assumptions!B186*Assumptions!B187+Assumptions!B190*Assumptions!B191)*(1+Assumptions!B194/100)^(4-1) | G5: =(Assumptions!B178*Assumptions!B179+Assumptions!B180*Assumptions!B181*Assumptions!B182+Assumptions!B186*Assumptions!B187+Assumptions!B190*Assumptions!B191)*(1+Assumptions!B194/100)^(5-1) | H5: =(Assumptions!B178*Assumptions!B179+Assumptions!B180*Assumptions!B181*Assumptions!B182+Assumptions!B186*Assumptions!B187+Assumptions!B190*Assumptions!B191)*(1+Assumptions!B194/100)^(6-1) | I5: =(Assumptions!B178*Assumptions!B179+Assumptions!B180*Assumptions!B181*Assumptions!B182+Assumptions!B186*Assumptions!B187+Assumptions!B190*Assumptions!B191)*(1+Assumptions!B194/100)^(7-1) | J5: =(Assumptions!B178*Assumptions!B179+Assumptions!B180*Assumptions!B181*Assumptions!B182+Assumptions!B186*Assumptions!B187+Assumptions!B190*Assumptions!B191)*(1+Assumptions!B194/100)^(8-1) | K5: =(Assumptions!B178*Assumptions!B179+Assumptions!B180*Assumptions!B181*Assumptions!B182+Assumptions!B186*Assumptions!B187+Assumptions!B190*Assumptions!B191)*(1+Assumptions!B194/100)^(9-1) | L5: =(Assumptions!B178*Assumptions!B179+Assumptions!B180*Assumptions!B181*Assumptions!B182+Assumptions!B186*Assumptions!B187+Assumptions!B190*Assumptions!B191)*(1+Assumptions!B194/100)^(10-1)
A6: Processing Consumables | B6: 0 | C6: =(Assumptions!B197*Assumptions!B24*Assumptions!B198+Assumptions!B201*Assumptions!B17*Assumptions!B202+Assumptions!B205*Assumptions!B24*Assumptions!B206+Assumptions!B209*(Assumptions!B17+Assumptions!B24)*Assumptions!B210+Assumptions!B213+Assumptions!B216+Assumptions!B219)*(1+Assumptions!B211/100)^(1-1) | D6: =(Assumptions!B197*Assumptions!B24*Assumptions!B198+Assumptions!B201*Assumptions!B17*Assumptions!B202+Assumptions!B205*Assumptions!B24*Assumptions!B206+Assumptions!B209*(Assumptions!B17+Assumptions!B24)*Assumptions!B210+Assumptions!B213+Assumptions!B216+Assumptions!B219)*(1+Assumptions!B211/100)^(2-1) | E6: =(Assumptions!B197*Assumptions!B24*Assumptions!B198+Assumptions!B201*Assumptions!B17*Assumptions!B202+Assumptions!B205*Assumptions!B24*Assumptions!B206+Assumptions!B209*(Assumptions!B17+Assumptions!B24)*Assumptions!B210+Assumptions!B213+Assumptions!B216+Assumptions!B219)*(1+Assumptions!B211/100)^(3-1) | F6: =(Assumptions!B197*Assumptions!B24*Assumptions!B198+Assumptions!B201*Assumptions!B17*Assumptions!B202+Assumptions!B205*Assumptions!B24*Assumptions!B206+Assumptions!B209*(Assumptions!B17+Assumptions!B24)*Assumptions!B210+Assumptions!B213+Assumptions!B216+Assumptions!B219)*(1+Assumptions!B211/100)^(4-1) | G6: =(Assumptions!B197*Assumptions!B24*Assumptions!B198+Assumptions!B201*Assumptions!B17*Assumptions!B202+Assumptions!B205*Assumptions!B24*Assumptions!B206+Assumptions!B209*(Assumptions!B17+Assumptions!B24)*Assumptions!B210+Assumptions!B213+Assumptions!B216+Assumptions!B219)*(1+Assumptions!B211/100)^(5-1) | H6: =(Assumptions!B197*Assumptions!B24*Assumptions!B198+Assumptions!B201*Assumptions!B17*Assumptions!B202+Assumptions!B205*Assumptions!B24*Assumptions!B206+Assumptions!B209*(Assumptions!B17+Assumptions!B24)*Assumptions!B210+Assumptions!B213+Assumptions!B216+Assumptions!B219)*(1+Assumptions!B211/100)^(6-1) | I6: =(Assumptions!B197*Assumptions!B24*Assumptions!B198+Assumptions!B201*Assumptions!B17*Assumptions!B202+Assumptions!B205*Assumptions!B24*Assumptions!B206+Assumptions!B209*(Assumptions!B17+Assumptions!B24)*Assumptions!B210+Assumptions!B213+Assumptions!B216+Assumptions!B219)*(1+Assumptions!B211/100)^(7-1) | J6: =(Assumptions!B197*Assumptions!B24*Assumptions!B198+Assumptions!B201*Assumptions!B17*Assumptions!B202+Assumptions!B205*Assumptions!B24*Assumptions!B206+Assumptions!B209*(Assumptions!B17+Assumptions!B24)*Assumptions!B210+Assumptions!B213+Assumptions!B216+Assumptions!B219)*(1+Assumptions!B211/100)^(8-1) | K6: =(Assumptions!B197*Assumptions!B24*Assumptions!B198+Assumptions!B201*Assumptions!B17*Assumptions!B202+Assumptions!B205*Assumptions!B24*Assumptions!B206+Assumptions!B209*(Assumptions!B17+Assumptions!B24)*Assumptions!B210+Assumptions!B213+Assumptions!B216+Assumptions!B219)*(1+Assumptions!B211/100)^(9-1) | L6: =(Assumptions!B197*Assumptions!B24*Assumptions!B198+Assumptions!B201*Assumptions!B17*Assumptions!B202+Assumptions!B205*Assumptions!B24*Assumptions!B206+Assumptions!B209*(Assumptions!B17+Assumptions!B24)*Assumptions!B210+Assumptions!B213+Assumptions!B216+Assumptions!B219)*(1+Assumptions!B211/100)^(10-1)
A7: Other Operating Costs | B7: 0 | C7: =(Calculations!$B$9*Assumptions!B223/100+Assumptions!B224+IF(1=1,Assumptions!B225,Assumptions!B226)+Assumptions!B227+Assumptions!B228+Assumptions!B229+Assumptions!B230+Assumptions!B231+Assumptions!B232+Assumptions!B233+Assumptions!B234)*(1+Assumptions!B235/100)^(1-1) | D7: =(Calculations!$B$9*Assumptions!B223/100+Assumptions!B224+IF(2=1,Assumptions!B225,Assumptions!B226)+Assumptions!B227+Assumptions!B228+Assumptions!B229+Assumptions!B230+Assumptions!B231+Assumptions!B232+Assumptions!B233+Assumptions!B234)*(1+Assumptions!B235/100)^(2-1) | E7: =(Calculations!$B$9*Assumptions!B223/100+Assumptions!B224+IF(3=1,Assumptions!B225,Assumptions!B226)+Assumptions!B227+Assumptions!B228+Assumptions!B229+Assumptions!B230+Assumptions!B231+Assumptions!B232+Assumptions!B233+Assumptions!B234)*(1+Assumptions!B235/100)^(3-1) | F7: =(Calculations!$B$9*Assumptions!B223/100+Assumptions!B224+IF(4=1,Assumptions!B225,Assumptions!B226)+Assumptions!B227+Assumptions!B228+Assumptions!B229+Assumptions!B230+Assumptions!B231+Assumptions!B232+Assumptions!B233+Assumptions!B234)*(1+Assumptions!B235/100)^(4-1) | G7: =(Calculations!$B$9*Assumptions!B223/100+Assumptions!B224+IF(5=1,Assumptions!B225,Assumptions!B226)+Assumptions!B227+Assumptions!B228+Assumptions!B229+Assumptions!B230+Assumptions!B231+Assumptions!B232+Assumptions!B233+Assumptions!B234)*(1+Assumptions!B235/100)^(5-1) | H7: =(Calculations!$B$9*Assumptions!B223/100+Assumptions!B224+IF(6=1,Assumptions!B225,Assumptions!B226)+Assumptions!B227+Assumptions!B228+Assumptions!B229+Assumptions!B230+Assumptions!B231+Assumptions!B232+Assumptions!B233+Assumptions!B234)*(1+Assumptions!B235/100)^(6-1) | I7: =(Calculations!$B$9*Assumptions!B223/100+Assumptions!B224+IF(7=1,Assumptions!B225,Assumptions!B226)+Assumptions!B227+Assumptions!B228+Assumptions!B229+Assumptions!B230+Assumptions!B231+Assumptions!B232+Assumptions!B233+Assumptions!B234)*(1+Assumptions!B235/100)^(7-1) | J7: =(Calculations!$B$9*Assumptions!B223/100+Assumptions!B224+IF(8=1,Assumptions!B225,Assumptions!B226)+Assumptions!B227+Assumptions!B228+Assumptions!B229+Assumptions!B230+Assumptions!B231+Assumptions!B232+Assumptions!B233+Assumptions!B234)*(1+Assumptions!B235/100)^(8-1) | K7: =(Calculations!$B$9*Assumptions!B223/100+Assumptions!B224+IF(9=1,Assumptions!B225,Assumptions!B226)+Assumptions!B227+Assumptions!B228+Assumptions!B229+Assumptions!B230+Assumptions!B231+Assumptions!B232+Assumptions!B233+Assumptions!B234)*(1+Assumptions!B235/100)^(9-1) | L7: =(Calculations!$B$9*Assumptions!B223/100+Assumptions!B224+IF(10=1,Assumptions!B225,Assumptions!B226)+Assumptions!B227+Assumptions!B228+Assumptions!B229+Assumptions!B230+Assumptions!B231+Assumptions!B232+Assumptions!B233+Assumptions!B234)*(1+Assumptions!B235/100)^(10-1)
A8: Regional Depot Operating Costs | B8: 0 | C8: =IF(1>=2,(Assumptions!B305+Assumptions!B306+Assumptions!B307+Assumptions!B308)*12,0)+IF(1>=3,(Assumptions!B310+Assumptions!B311+Assumptions!B312+Assumptions!B313+Assumptions!B315+Assumptions!B316+Assumptions!B317+Assumptions!B318+Assumptions!B320+Assumptions!B321+Assumptions!B322+Assumptions!B323)*12,0) | D8: =IF(2>=2,(Assumptions!B305+Assumptions!B306+Assumptions!B307+Assumptions!B308)*12,0)+IF(2>=3,(Assumptions!B310+Assumptions!B311+Assumptions!B312+Assumptions!B313+Assumptions!B315+Assumptions!B316+Assumptions!B317+Assumptions!B318+Assumptions!B320+Assumptions!B321+Assumptions!B322+Assumptions!B323)*12,0) | E8: =IF(3>=2,(Assumptions!B305+Assumptions!B306+Assumptions!B307+Assumptions!B308)*12,0)+IF(3>=3,(Assumptions!B310+Assumptions!B311+Assumptions!B312+Assumptions!B313+Assumptions!B315+Assumptions!B316+Assumptions!B317+Assumptions!B318+Assumptions!B320+Assumptions!B321+Assumptions!B322+Assumptions!B323)*12,0) | F8: =IF(4>=2,(Assumptions!B305+Assumptions!B306+Assumptions!B307+Assumptions!B308)*12,0)+IF(4>=3,(Assumptions!B310+Assumptions!B311+Assumptions!B312+Assumptions!B313+Assumptions!B315+Assumptions!B316+Assumptions!B317+Assumptions!B318+Assumptions!B320+Assumptions!B321+Assumptions!B322+Assumptions!B323)*12,0) | G8: =IF(5>=2,(Assumptions!B305+Assumptions!B306+Assumptions!B307+Assumptions!B308)*12,0)+IF(5>=3,(Assumptions!B310+Assumptions!B311+Assumptions!B312+Assumptions!B313+Assumptions!B315+Assumptions!B316+Assumptions!B317+Assumptions!B318+Assumptions!B320+Assumptions!B321+Assumptions!B322+Assumptions!B323)*12,0) | H8: =IF(6>=2,(Assumptions!B305+Assumptions!B306+Assumptions!B307+Assumptions!B308)*12,0)+IF(6>=3,(Assumptions!B310+Assumptions!B311+Assumptions!B312+Assumptions!B313+Assumptions!B315+Assumptions!B316+Assumptions!B317+Assumptions!B318+Assumptions!B320+Assumptions!B321+Assumptions!B322+Assumptions!B323)*12,0) | I8: =IF(7>=2,(Assumptions!B305+Assumptions!B306+Assumptions!B307+Assumptions!B308)*12,0)+IF(7>=3,(Assumptions!B310+Assumptions!B311+Assumptions!B312+Assumptions!B313+Assumptions!B315+Assumptions!B316+Assumptions!B317+Assumptions!B318+Assumptions!B320+Assumptions!B321+Assumptions!B322+Assumptions!B323)*12,0) | J8: =IF(8>=2,(Assumptions!B305+Assumptions!B306+Assumptions!B307+Assumptions!B308)*12,0)+IF(8>=3,(Assumptions!B310+Assumptions!B311+Assumptions!B312+Assumptions!B313+Assumptions!B315+Assumptions!B316+Assumptions!B317+Assumptions!B318+Assumptions!B320+Assumptions!B321+Assumptions!B322+Assumptions!B323)*12,0) | K8: =IF(9>=2,(Assumptions!B305+Assumptions!B306+Assumptions!B307+Assumptions!B308)*12,0)+IF(9>=3,(Assumptions!B310+Assumptions!B311+Assumptions!B312+Assumptions!B313+Assumptions!B315+Assumptions!B316+Assumptions!B317+Assumptions!B318+Assumptions!B320+Assumptions!B321+Assumptions!B322+Assumptions!B323)*12,0) | L8: =IF(10>=2,(Assumptions!B305+Assumptions!B306+Assumptions!B307+Assumptions!B308)*12,0)+IF(10>=3,(Assumptions!B310+Assumptions!B311+Assumptions!B312+Assumptions!B313+Assumptions!B315+Assumptions!B316+Assumptions!B317+Assumptions!B318+Assumptions!B320+Assumptions!B321+Assumptions!B322+Assumptions!B323)*12,0)
A9: TOTAL OPERATING COSTS | B9: =SUM(B3:B8) | C9: =SUM(C3:C8) | D9: =SUM(D3:D8) | E9: =SUM(E3:E8) | F9: =SUM(F3:F8) | G9: =SUM(G3:G8) | H9: =SUM(H3:H8) | I9: =SUM(I3:I8) | ... L9: =SUM(L3:L8)

Sheet CAPEX Schedule
A1: CAPITAL EXPENDITURE SCHEDULE
A2: CAPEX Category | B2: Year 0 | C2: Year 1 | D2: Year 2 | E2: Year 3 | F2: Year 4 | G2: Year 5 | H2: Year 6 | I2: Year 7 | J2: Year 8 | K2: Year 9 | L2: Year 10
A3: Phase 1 - Foundation Infrastructure | B3: =Calculations!B6*(1+Assumptions!B284/100) | C3: 0
A4: Phase 2 - Frozen Line & Douala Depot | B4: 0 | C4: 0 | D4: =Calculations!B7*(1+Assumptions!B293/100)
A5: Phase 3 - Regional Depot Expansion | B5: 0 | C5: 0 | D5: 0 | E5: =Calculations!B8*(1+Assumptions!B301/100)
A6: TOTAL CAPEX | B6: =SUM(B3:B5) | C6: =SUM(C3:C5) | D6: =SUM(D3:D5) | E6: =SUM(E3:E5) | F6: =SUM(F3:F5) | G6: =SUM(G3:G5) | H6: =SUM(H3:H5) | I6: =SUM(I3:I5) | ... L6: =SUM(L3:L5)

Sheet P&L Statement
A1: PROFIT & LOSS STATEMENT
A2: P&L Line Item | B2: Year 0 | C2: Year 1 | D2: Year 2 | E2: Year 3 | F2: Year 4 | G2: Year 5 | H2: Year 6 | I2: Year 7 | J2: Year 8 | K2: Year 9 | L2: Year 10
A3: Total Revenue | B3: =Revenue!B7 | C3: =Revenue!C7 | D3: =Revenue!D7 | E3: =Revenue!E7 | F3: =Revenue!F7 | G3: =Revenue!G7 | H3: =Revenue!H7 | I3: =Revenue!I7 | ... L3: =Revenue!L7
A4: Cost of Sales - Raw Materials | B4: =-'Operating Costs'!B3 | C4: =-'Operating Costs'!C3 | D4: =-'Operating Costs'!D3 | E4: =-'Operating Costs'!E3 | F4: =-'Operating Costs'!F3 | G4: =-'Operating Costs'!G3 | H4: =-'Operating Costs'!H3 | I4: =-'Operating Costs'!I3 | ... L4: =-'Operating Costs'!L3
A5: Gross Profit | B5: =B3+B4 | C5: =C3+C4 | D5: =D3+D4 | E5: =E3+E4 | F5: =F3+F4 | G5: =G3+G4 | H5: =H3+H4 | I5: =I3+I4 | ... L5: =L3+L4
A6: Operating Expenses | B6: =-SUM('Operating Costs'!B4:B8) | C6: =-SUM('Operating Costs'!C4:C8) | D6: =-SUM('Operating Costs'!D4:D8) | E6: =-SUM('Operating Costs'!E4:E8) | F6: =-SUM('Operating Costs'!F4:F8) | G6: =-SUM('Operating Costs'!G4:G8) | H6: =-SUM('Operating Costs'!H4:H8) | I6: =-SUM('Operating Costs'!I4:I8) | ... L6: =-SUM('Operating Costs'!L4:L8)
A7: EBITDA | B7: =B5+B6 | C7: =C5+C6 | D7: =D5+D6 | E7: =E5+E6 | F7: =F5+F6 | G7: =G5+G6 | H7: =H5+H6 | I7: =I5+I6 | ... L7: =L5+L6
A8: Depreciation | B8: =-Calculations!$B$9*0.1 | C8: =-Calculations!$B$9*0.1 | D8: =-Calculations!$B$9*0.1 | E8: =-Calculations!$B$9*0.1 | F8: =-Calculations!$B$9*0.1 | G8: =-Calculations!$B$9*0.1 | H8: =-Calculations!$B$9*0.1 | I8: =-Calculations!$B$9*0.1 | ... L8: =-Calculations!$B$9*0.1
A9: EBIT | B9: =B7+B8 | C9: =C7+C8 | D9: =D7+D8 | E9: =E7+E8 | F9: =F7+F8 | G9: =G7+G8 | H9: =H7+H8 | I9: =I7+I8 | ... L9: =L7+L8
A10: Interest Expense | B10: =-Calculations!$B$9*0.5*Assumptions!B347/100 | C10: =-Calculations!$B$9*0.5*Assumptions!B347/100 | D10: =-Calculations!$B$9*0.5*Assumptions!B347/100 | E10: =-Calculations!$B$9*0.5*Assumptions!B347/100 | F10: =-Calculations!$B$9*0.5*Assumptions!B347/100 | G10: =-Calculations!$B$9*0.5*Assumptions!B347/100 | H10: =-Calculations!$B$9*0.5*Assumptions!B347/100 | I10: =-Calculations!$B$9*0.5*Assumptions!B347/100 | J10: =-Calculations!$B$9*0.5*Assumptions!B347/100 | K10: =-Calculations!$B$9*0.5*Assumptions!B347/100 | L10: =-Calculations!$B$9*0.5*Assumptions!B347/100
A11: Earnings Before Tax (EBT) | B11: =B9+B10 | C11: =C9+C10 | D11: =D9+D10 | E11: =E9+E10 | F11: =F9+F10 | G11: =G9+G10 | H11: =H9+H10 | I11: =I9+I10 | ... L11: =L9+L10
A12: Tax Expense | B12: =-IF(0<=Assumptions!B359,0,IF(0<=Assumptions!B359+5,MAX(0,B11)*Assumptions!B360/100,MAX(0,B11)*Assumptions!B358/100)) | C12: =-IF(1<=Assumptions!B359,0,IF(1<=Assumptions!B359+5,MAX(0,C11)*Assumptions!B360/100,MAX(0,C11)*Assumptions!B358/100)) | D12: =-IF(2<=Assumptions!B359,0,IF(2<=Assumptions!B359+5,MAX(0,D11)*Assumptions!B360/100,MAX(0,D11)*Assumptions!B358/100)) | E12: =-IF(3<=Assumptions!B359,0,IF(3<=Assumptions!B359+5,MAX(0,E11)*Assumptions!B360/100,MAX(0,E11)*Assumptions!B358/100)) | F12: =-IF(4<=Assumptions!B359,0,IF(4<=Assumptions!B359+5,MAX(0,F11)*Assumptions!B360/100,MAX(0,F11)*Assumptions!B358/100)) | G12: =-IF(5<=Assumptions!B359,0,IF(5<=Assumptions!B359+5,MAX(0,G11)*Assumptions!B360/100,MAX(0,G11)*Assumptions!B358/100)) | H12: =-IF(6<=Assumptions!B359,0,IF(6<=Assumptions!B359+5,MAX(0,H11)*Assumptions!B360/100,MAX(0,H11)*Assumptions!B358/100)) | I12: =-IF(7<=Assumptions!B359,0,IF(7<=Assumptions!B359+5,MAX(0,I11)*Assumptions!B360/100,MAX(0,I11)*Assumptions!B358/100)) | J12: =-IF(8<=Assumptions!B359,0,IF(8<=Assumptions!B359+5,MAX(0,J11)*Assumptions!B360/100,MAX(0,J11)*Assumptions!B358/100)) | K12: =-IF(9<=Assumptions!B359,0,IF(9<=Assumptions!B359+5,MAX(0,K11)*Assumptions!B360/100,MAX(0,K11)*Assumptions!B358/100)) | L12: =-IF(10<=Assumptions!B359,0,IF(10<=Assumptions!B359+5,MAX(0,L11)*Assumptions!B360/100,MAX(0,L11)*Assumptions!B358/100))
A13: NET INCOME | B13: =B11+B12 | C13: =C11+C12 | D13: =D11+D12 | E13: =E11+E12 | F13: =F11+F12 | G13: =G11+G12 | H13: =H11+H12 | I13: =I11+I12 | ... L13: =L11+L12

Sheet Cash Flow
A1: CASH FLOW STATEMENT
A2: Cash Flow Item | B2: Year 0 | C2: Year 1 | D2: Year 2 | E2: Year 3 | F2: Year 4 | G2: Year 5 | H2: Year 6 | I2: Year 7 | J2: Year 8 | K2: Year 9 | L2: Year 10
A3: OPERATING ACTIVITIES
A4: Net Income | B4: ='P&L Statement'!B13 | C4: ='P&L Statement'!C13 | D4: ='P&L Statement'!D13 | E4: ='P&L Statement'!E13 | F4: ='P&L Statement'!F13 | G4: ='P&L Statement'!G13 | H4: ='P&L Statement'!H13 | I4: ='P&L Statement'!I13 | ... L4: ='P&L Statement'!L13
A5: Add: Depreciation | B5: =-'P&L Statement'!B8 | C5: =-'P&L Statement'!C8 | D5: =-'P&L Statement'!D8 | E5: =-'P&L Statement'!E8 | F5: =-'P&L Statement'!F8 | G5: =-'P&L Statement'!G8 | H5: =-'P&L Statement'!H8 | I5: =-'P&L Statement'!I8 | ... L5: =-'P&L Statement'!L8
A6: Less: Working Capital Changes | B6: 0 | C6: =-(Revenue!C7-Revenue!B7)*0.1 | D6: =-(Revenue!D7-Revenue!C7)*0.1 | E6: =-(Revenue!E7-Revenue!D7)*0.1 | F6: =-(Revenue!F7-Revenue!E7)*0.1 | G6: =-(Revenue!G7-Revenue!F7)*0.1 | H6: =-(Revenue!H7-Revenue!G7)*0.1 | I6: =-(Revenue!I7-Revenue!H7)*0.1 | J6: =-(Revenue!J7-Revenue!I7)*0.1 | ... L6: =-(Revenue!L7-Revenue!K7)*0.1
A7: Net Operating Cash Flow | B7: =SUM(B4:B6) | C7: =SUM(C4:C6) | D7: =SUM(D4:D6) | E7: =SUM(E4:E6) | F7: =SUM(F4:F6) | G7: =SUM(G4:G6) | H7: =SUM(H4:H6) | I7: =SUM(I4:I6) | ... L7: =SUM(L4:L6)
A9: INVESTING ACTIVITIES
A10: CAPEX | B10: =-'CAPEX Schedule'!B6 | C10: =-'CAPEX Schedule'!C6 | D10: =-'CAPEX Schedule'!D6 | E10: =-'CAPEX Schedule'!E6 | F10: =-'CAPEX Schedule'!F6 | G10: =-'CAPEX Schedule'!G6 | H10: =-'CAPEX Schedule'!H6 | I10: =-'CAPEX Schedule'!I6 | ... L10: =-'CAPEX Schedule'!L6
A11: Net Investing Cash Flow | B11: =B10 | C11: =C10 | D11: =D10 | E11: =E10 | F11: =F10 | G11: =G10 | H11: =H10 | I11: =I10 | ... L11: =L10
A13: FINANCING ACTIVITIES
A14: Equity Investment | B14: =Calculations!$B$9*Assumptions!B345/100 | C14: 0 | D14: 0 | E14: 0 | F14: 0 | G14: 0 | H14: 0 | I14: 0 | J14: 0 | K14: 0 | L14: 0
A15: Debt Drawdown | B15: =Calculations!$B$9*(Assumptions!B346/100+Assumptions!B353/100) | C15: 0 | D15: 0 | E15: 0 | F15: 0 | G15: 0 | H15: 0 | I15: 0 | J15: 0 | K15: 0 | L15: 0
A16: Debt Repayment | B16: 0 | C16: 0 | D16: 0 | E16: 0 | F16: =-Calculations!$B$9*0.5/(Assumptions!B348-Assumptions!B349) | G16: =-Calculations!$B$9*0.5/(Assumptions!B348-Assumptions!B349) | H16: =-Calculations!$B$9*0.5/(Assumptions!B348-Assumptions!B349) | I16: =-Calculations!$B$9*0.5/(Assumptions!B348-Assumptions!B349) | J16: =-Calculations!$B$9*0.5/(Assumptions!B348-Assumptions!B349) | K16: =-Calculations!$B$9*0.5/(Assumptions!B348-Assumptions!B349) | L16: =-Calculations!$B$9*0.5/(Assumptions!B348-Assumptions!B349)
A17: Net Financing Cash Flow | B17: =SUM(B14:B16) | C17: =SUM(C14:C16) | D17: =SUM(D14:D16) | E17: =SUM(E14:E16) | F17: =SUM(F14:F16) | G17: =SUM(G14:G16) | H17: =SUM(H14:H16) | I17: =SUM(I14:I16) | ... L17: =SUM(L14:L16)
A19: NET CASH FLOW | B19: =B7+B11+B17 | C19: =C7+C11+C17 | D19: =D7+D11+D17 | E19: =E7+E11+E17 | F19: =F7+F11+F17 | G19: =G7+G11+G17 | H19: =H7+H11+H17 | I19: =I7+I11+I17 | ... L19: =L7+L11+L17
A20: Cumulative Cash Flow | B20: =B19 | C20: =B20+C19 | D20: =C20+D19 | E20: =D20+E19 | F20: =E20+F19 | G20: =F20+G19 | H20: =G20+H19 | I20: =H20+I19 | J20: =I20+J19 | ... L20: =K20+L19

Sheet Returns Analysis
A1: RETURNS ANALYSIS
A2: Metric | B2: Value | C2: Unit
A3: Project IRR | B3: =IRR('Cash Flow'!B19:L19)*100 | C3: %
A4: Project NPV @ Discount Rate | B4: =NPV(Assumptions!B389/100,'Cash Flow'!C19:L19)+'Cash Flow'!B19 | C4: XAF
A5: Equity IRR | B5: =IRR('Cash Flow'!B19:L19)*100 | C5: %
A6: Average DSCR (Years 1-10) | B6: =AVERAGE('P&L Statement'!C7:L7)/ABS(AVERAGE('P&L Statement'!C10:L10)) | C6: x
A7: Payback Period | B7: See Cumulative CF | C7: Years
A9: KEY BENCHMARKS
A10: Minimum Equity IRR Target | B10: =Assumptions!B344 | C10: %
A11: Discount Rate (WACC) | B11: =Assumptions!B389 | C11: %

Sheet Development Impact
A1: DEVELOPMENT IMPACT METRICS
A2: Impact Indicator | B2: Value | C2: Unit
A3: EMPLOYMENT IMPACT
A4: Direct Jobs - Construction Phase | B4: =Assumptions!B412 | C4: Jobs
A5: Direct Jobs - Operations Phase | B5: =Assumptions!B413 | C5: Jobs
A6: Women in Workforce (%) | B6: =Assumptions!B414 | C6: %
A7: Women Employed (Direct) | B7: =B6*B7/100 | C7: Jobs
A8: Indirect Jobs Created (Multiplier) | B8: =B6*Assumptions!B416 | C8: Jobs
A9: TOTAL JOBS CREATED | B9: =B6+B9 | C9: Jobs
A11: FARMER IMPACT
A12: Number of Farmers Supported | B12: =Assumptions!B135 | C12: Farmers
A13: Baseline Farmer Income (Annual) | B13: =Assumptions!B418 | C13: XAF/year
A14: Project Farmer Income (Annual) | B14: =Assumptions!B419 | C14: XAF/year
A15: Income Increase per Farmer | B15: =B16-B15 | C15: XAF/year
A16: Income Increase (%) | B16: =(B16-B15)/B15*100 | C16: %
A17: Women Farmers (%) | B17: =Assumptions!B420 | C17: %
A19: ECONOMIC IMPACT
A20: Local Content (% of costs sourced locally) | B20: =Assumptions!B422 | C20: %
A21: Import Substitution Value (Annual) | B21: =AVERAGE(Revenue!C4:L4)+AVERAGE(Revenue!C5:L5) | C21: XAF/year
A22: CO₂ Reduction (Transport emissions avoided) | B22: =Assumptions!B423 | C22: Tonnes/year

Sheet Documentation
A1: SANTA FRESH FINANCIAL MODEL - USER GUIDE
A3: OVERVIEW
A4: This financial model is designed for the EIC Integrated Potato Value Chain project.
A5: All inputs are entered in the Assumptions sheet. All other sheets auto-calculate.
A7: HOW TO USE THIS MODEL
A8: Step 1 | B8: Go to the Assumptions sheet
A9: Step 2 | B9: Find the BLUE cells in Column C - these are your inputs
A10: Step 3 | B10: Enter your values in the BLUE cells only
A11: Step 4 | B11: All other sheets will automatically calculate
A12: Step 5 | B12: Review results in Dashboard, P&L, Cash Flow, and Returns Analysis
A14: COLOR CODING
A15: BLUE cells | B15: Your inputs (editable)
A16: YELLOW cells | B16: Auto-calculated (don't edit)
A17: GREEN cells | B17: Scenario toggles (select from dropdown)
A18: WHITE cells | B18: Labels and headers (don't edit)
A20: SHEET DESCRIPTIONS
A21: Dashboard | B21: Executive summary with key metrics (Project IRR, NPV, EBITDA, Jobs Created)
A22: Assumptions | B22: ALL YOUR INPUTS GO HERE - 21 sections (A-U) covering project timeline, revenue, costs, CAPEX, financing, etc.
A23: Calculations | B23: Derived values auto-calculated from Assumptions (total CAPEX, capacity, etc.)
A24: Revenue | B24: Annual revenue by product line (Fresh-pack, Frozen, Seeds, Feed) with escalation
A25: Operating Costs | B25: Annual operating costs by category (Raw materials, Labor, Utilities, Consumables, Depots)
A26: CAPEX Schedule | B26: Capital expenditure by phase (Phase 1: Foundation, Phase 2: Frozen Line, Phase 3: Depots)
A27: P&L Statement | B27: Full income statement (Revenue → EBITDA → Net Income)
A28: Cash Flow | B28: Cash flow statement (Operating, Investing, Financing activities)
A29: Returns Analysis | B29: Investment metrics (Project IRR, NPV, Equity IRR, DSCR, Payback Period)
A30: Development Impact | B30: Social/economic impact (Jobs created, Farmer income, Import substitution)
A31: Documentation | B31: This user guide
A33: ASSUMPTIONS SHEET - INPUT SECTIONS
A34: Section A: Project Timeline & Phasing | B34: Model start year, construction duration by phase
A35: Section B: Revenue Streams & Products | B35: Fresh-pack, Frozen, Seeds, Feed volumes & prices
A36: Section C: Processing Capacity & Utilization | B36: Line capacities, operating hours, utilization ramp-up
A37: Section D: Raw Material Sourcing | B37: Ware potato pricing, sourcing mix, seasonality
A38: Section E: Seed Operations | B38: Traditional seeds (Agrico/HZPC), TPS nursery (Solynta), seeds-on-credit
A39: Section F: Outgrower Network | B39: Farmer targets, yields, input package costs
A40: Section G: EIC-Owned Farm | B40: Land size, lease costs, operations
A41: Section H: Operating Costs - Labor | B41: 7 departments (Management, Production, QC, Logistics, Sales, Field, Security)
A42: Section I: Operating Costs - Utilities | B42: Electricity, Water, Diesel consumption & pricing
A43: Section J: Operating Costs - Consumables | B43: Oil, Packaging, Additives, Cleaning, Maintenance, QC supplies
A44: Section K: Operating Costs - Other | B44: Insurance, Marketing, Admin, Licensing, etc.
A45: Section L: Waste Valorization | B45: Animal feed pelletizer operations
...
